INFO 2025-08-07 01:32:04,783 autoreload 30292 11408 Watching for file changes with StatReloader
INFO 2025-08-07 01:33:17,945 autoreload 17756 19300 Watching for file changes with StatReloader
ERROR 2025-08-07 01:34:42,634 log 17756 10872 Internal Server Error: /api/auth/register/
Traceback (most recent call last):
  File "C:\Users\Technomowj\AppData\Local\Programs\Python\Python313\Lib\site-packages\django\db\backends\utils.py", line 89, in _execute
    return self.cursor.execute(sql, params)
           ~~~~~~~~~~~~~~~~~~~^^^^^^^^^^^^^
  File "C:\Users\Technomowj\AppData\Local\Programs\Python\Python313\Lib\site-packages\django\db\backends\sqlite3\base.py", line 328, in execute
    return super().execute(query, params)
           ~~~~~~~~~~~~~~~^^^^^^^^^^^^^^^
sqlite3.OperationalError: no such table: game_user

The above exception was the direct cause of the following exception:

Traceback (most recent call last):
  File "C:\Users\Technomowj\AppData\Local\Programs\Python\Python313\Lib\site-packages\django\core\handlers\exception.py", line 55, in inner
    response = get_response(request)
  File "C:\Users\Technomowj\AppData\Local\Programs\Python\Python313\Lib\site-packages\django\core\handlers\base.py", line 197, in _get_response
    response = wrapped_callback(request, *callback_args, **callback_kwargs)
  File "C:\Users\Technomowj\AppData\Local\Programs\Python\Python313\Lib\site-packages\django\views\decorators\csrf.py", line 56, in wrapper_view
    return view_func(*args, **kwargs)
  File "C:\Users\Technomowj\AppData\Local\Programs\Python\Python313\Lib\site-packages\django\views\generic\base.py", line 104, in view
    return self.dispatch(request, *args, **kwargs)
           ~~~~~~~~~~~~~^^^^^^^^^^^^^^^^^^^^^^^^^^
  File "C:\Users\Technomowj\AppData\Local\Programs\Python\Python313\Lib\site-packages\rest_framework\views.py", line 509, in dispatch
    response = self.handle_exception(exc)
  File "C:\Users\Technomowj\AppData\Local\Programs\Python\Python313\Lib\site-packages\rest_framework\views.py", line 469, in handle_exception
    self.raise_uncaught_exception(exc)
    ~~~~~~~~~~~~~~~~~~~~~~~~~~~~~^^^^^
  File "C:\Users\Technomowj\AppData\Local\Programs\Python\Python313\Lib\site-packages\rest_framework\views.py", line 480, in raise_uncaught_exception
    raise exc
  File "C:\Users\Technomowj\AppData\Local\Programs\Python\Python313\Lib\site-packages\rest_framework\views.py", line 506, in dispatch
    response = handler(request, *args, **kwargs)
  File "C:\Users\Technomowj\AppData\Local\Programs\Python\Python313\Lib\site-packages\rest_framework\decorators.py", line 50, in handler
    return func(*args, **kwargs)
  File "D:\code\10\game\views.py", line 39, in register_user
    if serializer.is_valid():
       ~~~~~~~~~~~~~~~~~~~^^
  File "C:\Users\Technomowj\AppData\Local\Programs\Python\Python313\Lib\site-packages\rest_framework\serializers.py", line 227, in is_valid
    self._validated_data = self.run_validation(self.initial_data)
                           ~~~~~~~~~~~~~~~~~~~^^^^^^^^^^^^^^^^^^^
  File "C:\Users\Technomowj\AppData\Local\Programs\Python\Python313\Lib\site-packages\rest_framework\serializers.py", line 426, in run_validation
    value = self.to_internal_value(data)
  File "C:\Users\Technomowj\AppData\Local\Programs\Python\Python313\Lib\site-packages\rest_framework\serializers.py", line 483, in to_internal_value
    validated_value = field.run_validation(primitive_value)
  File "C:\Users\Technomowj\AppData\Local\Programs\Python\Python313\Lib\site-packages\rest_framework\fields.py", line 751, in run_validation
    return super().run_validation(data)
           ~~~~~~~~~~~~~~~~~~~~~~^^^^^^
  File "C:\Users\Technomowj\AppData\Local\Programs\Python\Python313\Lib\site-packages\rest_framework\fields.py", line 548, in run_validation
    self.run_validators(value)
    ~~~~~~~~~~~~~~~~~~~^^^^^^^
  File "C:\Users\Technomowj\AppData\Local\Programs\Python\Python313\Lib\site-packages\rest_framework\fields.py", line 560, in run_validators
    validator(value, self)
    ~~~~~~~~~^^^^^^^^^^^^^
  File "C:\Users\Technomowj\AppData\Local\Programs\Python\Python313\Lib\site-packages\rest_framework\validators.py", line 73, in __call__
    if qs_exists(queryset):
       ~~~~~~~~~^^^^^^^^^^
  File "C:\Users\Technomowj\AppData\Local\Programs\Python\Python313\Lib\site-packages\rest_framework\validators.py", line 21, in qs_exists
    return queryset.exists()
           ~~~~~~~~~~~~~~~^^
  File "C:\Users\Technomowj\AppData\Local\Programs\Python\Python313\Lib\site-packages\django\db\models\query.py", line 1241, in exists
    return self.query.has_results(using=self.db)
           ~~~~~~~~~~~~~~~~~~~~~~^^^^^^^^^^^^^^^
  File "C:\Users\Technomowj\AppData\Local\Programs\Python\Python313\Lib\site-packages\django\db\models\sql\query.py", line 598, in has_results
    return compiler.has_results()
           ~~~~~~~~~~~~~~~~~~~~^^
  File "C:\Users\Technomowj\AppData\Local\Programs\Python\Python313\Lib\site-packages\django\db\models\sql\compiler.py", line 1530, in has_results
    return bool(self.execute_sql(SINGLE))
                ~~~~~~~~~~~~~~~~^^^^^^^^
  File "C:\Users\Technomowj\AppData\Local\Programs\Python\Python313\Lib\site-packages\django\db\models\sql\compiler.py", line 1562, in execute_sql
    cursor.execute(sql, params)
    ~~~~~~~~~~~~~~^^^^^^^^^^^^^
  File "C:\Users\Technomowj\AppData\Local\Programs\Python\Python313\Lib\site-packages\django\db\backends\utils.py", line 102, in execute
    return super().execute(sql, params)
           ~~~~~~~~~~~~~~~^^^^^^^^^^^^^
  File "C:\Users\Technomowj\AppData\Local\Programs\Python\Python313\Lib\site-packages\django\db\backends\utils.py", line 67, in execute
    return self._execute_with_wrappers(
           ~~~~~~~~~~~~~~~~~~~~~~~~~~~^
        sql, params, many=False, executor=self._execute
        ^^^^^^^^^^^^^^^^^^^^^^^^^^^^^^^^^^^^^^^^^^^^^^^
    )
    ^
  File "C:\Users\Technomowj\AppData\Local\Programs\Python\Python313\Lib\site-packages\django\db\backends\utils.py", line 80, in _execute_with_wrappers
    return executor(sql, params, many, context)
  File "C:\Users\Technomowj\AppData\Local\Programs\Python\Python313\Lib\site-packages\django\db\backends\utils.py", line 84, in _execute
    with self.db.wrap_database_errors:
         ^^^^^^^^^^^^^^^^^^^^^^^^^^^^
  File "C:\Users\Technomowj\AppData\Local\Programs\Python\Python313\Lib\site-packages\django\db\utils.py", line 91, in __exit__
    raise dj_exc_value.with_traceback(traceback) from exc_value
  File "C:\Users\Technomowj\AppData\Local\Programs\Python\Python313\Lib\site-packages\django\db\backends\utils.py", line 89, in _execute
    return self.cursor.execute(sql, params)
           ~~~~~~~~~~~~~~~~~~~^^^^^^^^^^^^^
  File "C:\Users\Technomowj\AppData\Local\Programs\Python\Python313\Lib\site-packages\django\db\backends\sqlite3\base.py", line 328, in execute
    return super().execute(query, params)
           ~~~~~~~~~~~~~~~^^^^^^^^^^^^^^^
django.db.utils.OperationalError: no such table: game_user
ERROR 2025-08-07 01:35:25,027 log 17756 10872 Internal Server Error: /api/auth/register/
Traceback (most recent call last):
  File "C:\Users\Technomowj\AppData\Local\Programs\Python\Python313\Lib\site-packages\django\db\backends\utils.py", line 89, in _execute
    return self.cursor.execute(sql, params)
           ~~~~~~~~~~~~~~~~~~~^^^^^^^^^^^^^
  File "C:\Users\Technomowj\AppData\Local\Programs\Python\Python313\Lib\site-packages\django\db\backends\sqlite3\base.py", line 328, in execute
    return super().execute(query, params)
           ~~~~~~~~~~~~~~~^^^^^^^^^^^^^^^
sqlite3.OperationalError: no such table: game_user

The above exception was the direct cause of the following exception:

Traceback (most recent call last):
  File "C:\Users\Technomowj\AppData\Local\Programs\Python\Python313\Lib\site-packages\django\core\handlers\exception.py", line 55, in inner
    response = get_response(request)
  File "C:\Users\Technomowj\AppData\Local\Programs\Python\Python313\Lib\site-packages\django\core\handlers\base.py", line 197, in _get_response
    response = wrapped_callback(request, *callback_args, **callback_kwargs)
  File "C:\Users\Technomowj\AppData\Local\Programs\Python\Python313\Lib\site-packages\django\views\decorators\csrf.py", line 56, in wrapper_view
    return view_func(*args, **kwargs)
  File "C:\Users\Technomowj\AppData\Local\Programs\Python\Python313\Lib\site-packages\django\views\generic\base.py", line 104, in view
    return self.dispatch(request, *args, **kwargs)
           ~~~~~~~~~~~~~^^^^^^^^^^^^^^^^^^^^^^^^^^
  File "C:\Users\Technomowj\AppData\Local\Programs\Python\Python313\Lib\site-packages\rest_framework\views.py", line 509, in dispatch
    response = self.handle_exception(exc)
  File "C:\Users\Technomowj\AppData\Local\Programs\Python\Python313\Lib\site-packages\rest_framework\views.py", line 469, in handle_exception
    self.raise_uncaught_exception(exc)
    ~~~~~~~~~~~~~~~~~~~~~~~~~~~~~^^^^^
  File "C:\Users\Technomowj\AppData\Local\Programs\Python\Python313\Lib\site-packages\rest_framework\views.py", line 480, in raise_uncaught_exception
    raise exc
  File "C:\Users\Technomowj\AppData\Local\Programs\Python\Python313\Lib\site-packages\rest_framework\views.py", line 506, in dispatch
    response = handler(request, *args, **kwargs)
  File "C:\Users\Technomowj\AppData\Local\Programs\Python\Python313\Lib\site-packages\rest_framework\decorators.py", line 50, in handler
    return func(*args, **kwargs)
  File "D:\code\10\game\views.py", line 39, in register_user
    if serializer.is_valid():
       ~~~~~~~~~~~~~~~~~~~^^
  File "C:\Users\Technomowj\AppData\Local\Programs\Python\Python313\Lib\site-packages\rest_framework\serializers.py", line 227, in is_valid
    self._validated_data = self.run_validation(self.initial_data)
                           ~~~~~~~~~~~~~~~~~~~^^^^^^^^^^^^^^^^^^^
  File "C:\Users\Technomowj\AppData\Local\Programs\Python\Python313\Lib\site-packages\rest_framework\serializers.py", line 426, in run_validation
    value = self.to_internal_value(data)
  File "C:\Users\Technomowj\AppData\Local\Programs\Python\Python313\Lib\site-packages\rest_framework\serializers.py", line 483, in to_internal_value
    validated_value = field.run_validation(primitive_value)
  File "C:\Users\Technomowj\AppData\Local\Programs\Python\Python313\Lib\site-packages\rest_framework\fields.py", line 751, in run_validation
    return super().run_validation(data)
           ~~~~~~~~~~~~~~~~~~~~~~^^^^^^
  File "C:\Users\Technomowj\AppData\Local\Programs\Python\Python313\Lib\site-packages\rest_framework\fields.py", line 548, in run_validation
    self.run_validators(value)
    ~~~~~~~~~~~~~~~~~~~^^^^^^^
  File "C:\Users\Technomowj\AppData\Local\Programs\Python\Python313\Lib\site-packages\rest_framework\fields.py", line 560, in run_validators
    validator(value, self)
    ~~~~~~~~~^^^^^^^^^^^^^
  File "C:\Users\Technomowj\AppData\Local\Programs\Python\Python313\Lib\site-packages\rest_framework\validators.py", line 73, in __call__
    if qs_exists(queryset):
       ~~~~~~~~~^^^^^^^^^^
  File "C:\Users\Technomowj\AppData\Local\Programs\Python\Python313\Lib\site-packages\rest_framework\validators.py", line 21, in qs_exists
    return queryset.exists()
           ~~~~~~~~~~~~~~~^^
  File "C:\Users\Technomowj\AppData\Local\Programs\Python\Python313\Lib\site-packages\django\db\models\query.py", line 1241, in exists
    return self.query.has_results(using=self.db)
           ~~~~~~~~~~~~~~~~~~~~~~^^^^^^^^^^^^^^^
  File "C:\Users\Technomowj\AppData\Local\Programs\Python\Python313\Lib\site-packages\django\db\models\sql\query.py", line 598, in has_results
    return compiler.has_results()
           ~~~~~~~~~~~~~~~~~~~~^^
  File "C:\Users\Technomowj\AppData\Local\Programs\Python\Python313\Lib\site-packages\django\db\models\sql\compiler.py", line 1530, in has_results
    return bool(self.execute_sql(SINGLE))
                ~~~~~~~~~~~~~~~~^^^^^^^^
  File "C:\Users\Technomowj\AppData\Local\Programs\Python\Python313\Lib\site-packages\django\db\models\sql\compiler.py", line 1562, in execute_sql
    cursor.execute(sql, params)
    ~~~~~~~~~~~~~~^^^^^^^^^^^^^
  File "C:\Users\Technomowj\AppData\Local\Programs\Python\Python313\Lib\site-packages\django\db\backends\utils.py", line 102, in execute
    return super().execute(sql, params)
           ~~~~~~~~~~~~~~~^^^^^^^^^^^^^
  File "C:\Users\Technomowj\AppData\Local\Programs\Python\Python313\Lib\site-packages\django\db\backends\utils.py", line 67, in execute
    return self._execute_with_wrappers(
           ~~~~~~~~~~~~~~~~~~~~~~~~~~~^
        sql, params, many=False, executor=self._execute
        ^^^^^^^^^^^^^^^^^^^^^^^^^^^^^^^^^^^^^^^^^^^^^^^
    )
    ^
  File "C:\Users\Technomowj\AppData\Local\Programs\Python\Python313\Lib\site-packages\django\db\backends\utils.py", line 80, in _execute_with_wrappers
    return executor(sql, params, many, context)
  File "C:\Users\Technomowj\AppData\Local\Programs\Python\Python313\Lib\site-packages\django\db\backends\utils.py", line 84, in _execute
    with self.db.wrap_database_errors:
         ^^^^^^^^^^^^^^^^^^^^^^^^^^^^
  File "C:\Users\Technomowj\AppData\Local\Programs\Python\Python313\Lib\site-packages\django\db\utils.py", line 91, in __exit__
    raise dj_exc_value.with_traceback(traceback) from exc_value
  File "C:\Users\Technomowj\AppData\Local\Programs\Python\Python313\Lib\site-packages\django\db\backends\utils.py", line 89, in _execute
    return self.cursor.execute(sql, params)
           ~~~~~~~~~~~~~~~~~~~^^^^^^^^^^^^^
  File "C:\Users\Technomowj\AppData\Local\Programs\Python\Python313\Lib\site-packages\django\db\backends\sqlite3\base.py", line 328, in execute
    return super().execute(query, params)
           ~~~~~~~~~~~~~~~^^^^^^^^^^^^^^^
django.db.utils.OperationalError: no such table: game_user
WARNING 2025-08-07 01:35:30,317 log 17756 10872 Not Found: /.well-known/appspecific/com.chrome.devtools.json
ERROR 2025-08-07 01:35:35,002 log 17756 10872 Internal Server Error: /api/auth/register/
Traceback (most recent call last):
  File "C:\Users\Technomowj\AppData\Local\Programs\Python\Python313\Lib\site-packages\django\db\backends\utils.py", line 89, in _execute
    return self.cursor.execute(sql, params)
           ~~~~~~~~~~~~~~~~~~~^^^^^^^^^^^^^
  File "C:\Users\Technomowj\AppData\Local\Programs\Python\Python313\Lib\site-packages\django\db\backends\sqlite3\base.py", line 328, in execute
    return super().execute(query, params)
           ~~~~~~~~~~~~~~~^^^^^^^^^^^^^^^
sqlite3.OperationalError: no such table: game_user

The above exception was the direct cause of the following exception:

Traceback (most recent call last):
  File "C:\Users\Technomowj\AppData\Local\Programs\Python\Python313\Lib\site-packages\django\core\handlers\exception.py", line 55, in inner
    response = get_response(request)
  File "C:\Users\Technomowj\AppData\Local\Programs\Python\Python313\Lib\site-packages\django\core\handlers\base.py", line 197, in _get_response
    response = wrapped_callback(request, *callback_args, **callback_kwargs)
  File "C:\Users\Technomowj\AppData\Local\Programs\Python\Python313\Lib\site-packages\django\views\decorators\csrf.py", line 56, in wrapper_view
    return view_func(*args, **kwargs)
  File "C:\Users\Technomowj\AppData\Local\Programs\Python\Python313\Lib\site-packages\django\views\generic\base.py", line 104, in view
    return self.dispatch(request, *args, **kwargs)
           ~~~~~~~~~~~~~^^^^^^^^^^^^^^^^^^^^^^^^^^
  File "C:\Users\Technomowj\AppData\Local\Programs\Python\Python313\Lib\site-packages\rest_framework\views.py", line 509, in dispatch
    response = self.handle_exception(exc)
  File "C:\Users\Technomowj\AppData\Local\Programs\Python\Python313\Lib\site-packages\rest_framework\views.py", line 469, in handle_exception
    self.raise_uncaught_exception(exc)
    ~~~~~~~~~~~~~~~~~~~~~~~~~~~~~^^^^^
  File "C:\Users\Technomowj\AppData\Local\Programs\Python\Python313\Lib\site-packages\rest_framework\views.py", line 480, in raise_uncaught_exception
    raise exc
  File "C:\Users\Technomowj\AppData\Local\Programs\Python\Python313\Lib\site-packages\rest_framework\views.py", line 506, in dispatch
    response = handler(request, *args, **kwargs)
  File "C:\Users\Technomowj\AppData\Local\Programs\Python\Python313\Lib\site-packages\rest_framework\decorators.py", line 50, in handler
    return func(*args, **kwargs)
  File "D:\code\10\game\views.py", line 39, in register_user
    if serializer.is_valid():
       ~~~~~~~~~~~~~~~~~~~^^
  File "C:\Users\Technomowj\AppData\Local\Programs\Python\Python313\Lib\site-packages\rest_framework\serializers.py", line 227, in is_valid
    self._validated_data = self.run_validation(self.initial_data)
                           ~~~~~~~~~~~~~~~~~~~^^^^^^^^^^^^^^^^^^^
  File "C:\Users\Technomowj\AppData\Local\Programs\Python\Python313\Lib\site-packages\rest_framework\serializers.py", line 426, in run_validation
    value = self.to_internal_value(data)
  File "C:\Users\Technomowj\AppData\Local\Programs\Python\Python313\Lib\site-packages\rest_framework\serializers.py", line 483, in to_internal_value
    validated_value = field.run_validation(primitive_value)
  File "C:\Users\Technomowj\AppData\Local\Programs\Python\Python313\Lib\site-packages\rest_framework\fields.py", line 751, in run_validation
    return super().run_validation(data)
           ~~~~~~~~~~~~~~~~~~~~~~^^^^^^
  File "C:\Users\Technomowj\AppData\Local\Programs\Python\Python313\Lib\site-packages\rest_framework\fields.py", line 548, in run_validation
    self.run_validators(value)
    ~~~~~~~~~~~~~~~~~~~^^^^^^^
  File "C:\Users\Technomowj\AppData\Local\Programs\Python\Python313\Lib\site-packages\rest_framework\fields.py", line 560, in run_validators
    validator(value, self)
    ~~~~~~~~~^^^^^^^^^^^^^
  File "C:\Users\Technomowj\AppData\Local\Programs\Python\Python313\Lib\site-packages\rest_framework\validators.py", line 73, in __call__
    if qs_exists(queryset):
       ~~~~~~~~~^^^^^^^^^^
  File "C:\Users\Technomowj\AppData\Local\Programs\Python\Python313\Lib\site-packages\rest_framework\validators.py", line 21, in qs_exists
    return queryset.exists()
           ~~~~~~~~~~~~~~~^^
  File "C:\Users\Technomowj\AppData\Local\Programs\Python\Python313\Lib\site-packages\django\db\models\query.py", line 1241, in exists
    return self.query.has_results(using=self.db)
           ~~~~~~~~~~~~~~~~~~~~~~^^^^^^^^^^^^^^^
  File "C:\Users\Technomowj\AppData\Local\Programs\Python\Python313\Lib\site-packages\django\db\models\sql\query.py", line 598, in has_results
    return compiler.has_results()
           ~~~~~~~~~~~~~~~~~~~~^^
  File "C:\Users\Technomowj\AppData\Local\Programs\Python\Python313\Lib\site-packages\django\db\models\sql\compiler.py", line 1530, in has_results
    return bool(self.execute_sql(SINGLE))
                ~~~~~~~~~~~~~~~~^^^^^^^^
  File "C:\Users\Technomowj\AppData\Local\Programs\Python\Python313\Lib\site-packages\django\db\models\sql\compiler.py", line 1562, in execute_sql
    cursor.execute(sql, params)
    ~~~~~~~~~~~~~~^^^^^^^^^^^^^
  File "C:\Users\Technomowj\AppData\Local\Programs\Python\Python313\Lib\site-packages\django\db\backends\utils.py", line 102, in execute
    return super().execute(sql, params)
           ~~~~~~~~~~~~~~~^^^^^^^^^^^^^
  File "C:\Users\Technomowj\AppData\Local\Programs\Python\Python313\Lib\site-packages\django\db\backends\utils.py", line 67, in execute
    return self._execute_with_wrappers(
           ~~~~~~~~~~~~~~~~~~~~~~~~~~~^
        sql, params, many=False, executor=self._execute
        ^^^^^^^^^^^^^^^^^^^^^^^^^^^^^^^^^^^^^^^^^^^^^^^
    )
    ^
  File "C:\Users\Technomowj\AppData\Local\Programs\Python\Python313\Lib\site-packages\django\db\backends\utils.py", line 80, in _execute_with_wrappers
    return executor(sql, params, many, context)
  File "C:\Users\Technomowj\AppData\Local\Programs\Python\Python313\Lib\site-packages\django\db\backends\utils.py", line 84, in _execute
    with self.db.wrap_database_errors:
         ^^^^^^^^^^^^^^^^^^^^^^^^^^^^
  File "C:\Users\Technomowj\AppData\Local\Programs\Python\Python313\Lib\site-packages\django\db\utils.py", line 91, in __exit__
    raise dj_exc_value.with_traceback(traceback) from exc_value
  File "C:\Users\Technomowj\AppData\Local\Programs\Python\Python313\Lib\site-packages\django\db\backends\utils.py", line 89, in _execute
    return self.cursor.execute(sql, params)
           ~~~~~~~~~~~~~~~~~~~^^^^^^^^^^^^^
  File "C:\Users\Technomowj\AppData\Local\Programs\Python\Python313\Lib\site-packages\django\db\backends\sqlite3\base.py", line 328, in execute
    return super().execute(query, params)
           ~~~~~~~~~~~~~~~^^^^^^^^^^^^^^^
django.db.utils.OperationalError: no such table: game_user
ERROR 2025-08-07 01:36:07,827 log 17756 10872 Internal Server Error: /api/auth/register/
Traceback (most recent call last):
  File "C:\Users\Technomowj\AppData\Local\Programs\Python\Python313\Lib\site-packages\django\db\backends\utils.py", line 89, in _execute
    return self.cursor.execute(sql, params)
           ~~~~~~~~~~~~~~~~~~~^^^^^^^^^^^^^
  File "C:\Users\Technomowj\AppData\Local\Programs\Python\Python313\Lib\site-packages\django\db\backends\sqlite3\base.py", line 328, in execute
    return super().execute(query, params)
           ~~~~~~~~~~~~~~~^^^^^^^^^^^^^^^
sqlite3.OperationalError: no such table: game_user

The above exception was the direct cause of the following exception:

Traceback (most recent call last):
  File "C:\Users\Technomowj\AppData\Local\Programs\Python\Python313\Lib\site-packages\django\core\handlers\exception.py", line 55, in inner
    response = get_response(request)
  File "C:\Users\Technomowj\AppData\Local\Programs\Python\Python313\Lib\site-packages\django\core\handlers\base.py", line 197, in _get_response
    response = wrapped_callback(request, *callback_args, **callback_kwargs)
  File "C:\Users\Technomowj\AppData\Local\Programs\Python\Python313\Lib\site-packages\django\views\decorators\csrf.py", line 56, in wrapper_view
    return view_func(*args, **kwargs)
  File "C:\Users\Technomowj\AppData\Local\Programs\Python\Python313\Lib\site-packages\django\views\generic\base.py", line 104, in view
    return self.dispatch(request, *args, **kwargs)
           ~~~~~~~~~~~~~^^^^^^^^^^^^^^^^^^^^^^^^^^
  File "C:\Users\Technomowj\AppData\Local\Programs\Python\Python313\Lib\site-packages\rest_framework\views.py", line 509, in dispatch
    response = self.handle_exception(exc)
  File "C:\Users\Technomowj\AppData\Local\Programs\Python\Python313\Lib\site-packages\rest_framework\views.py", line 469, in handle_exception
    self.raise_uncaught_exception(exc)
    ~~~~~~~~~~~~~~~~~~~~~~~~~~~~~^^^^^
  File "C:\Users\Technomowj\AppData\Local\Programs\Python\Python313\Lib\site-packages\rest_framework\views.py", line 480, in raise_uncaught_exception
    raise exc
  File "C:\Users\Technomowj\AppData\Local\Programs\Python\Python313\Lib\site-packages\rest_framework\views.py", line 506, in dispatch
    response = handler(request, *args, **kwargs)
  File "C:\Users\Technomowj\AppData\Local\Programs\Python\Python313\Lib\site-packages\rest_framework\decorators.py", line 50, in handler
    return func(*args, **kwargs)
  File "D:\code\10\game\views.py", line 39, in register_user
    if serializer.is_valid():
       ~~~~~~~~~~~~~~~~~~~^^
  File "C:\Users\Technomowj\AppData\Local\Programs\Python\Python313\Lib\site-packages\rest_framework\serializers.py", line 227, in is_valid
    self._validated_data = self.run_validation(self.initial_data)
                           ~~~~~~~~~~~~~~~~~~~^^^^^^^^^^^^^^^^^^^
  File "C:\Users\Technomowj\AppData\Local\Programs\Python\Python313\Lib\site-packages\rest_framework\serializers.py", line 426, in run_validation
    value = self.to_internal_value(data)
  File "C:\Users\Technomowj\AppData\Local\Programs\Python\Python313\Lib\site-packages\rest_framework\serializers.py", line 483, in to_internal_value
    validated_value = field.run_validation(primitive_value)
  File "C:\Users\Technomowj\AppData\Local\Programs\Python\Python313\Lib\site-packages\rest_framework\fields.py", line 751, in run_validation
    return super().run_validation(data)
           ~~~~~~~~~~~~~~~~~~~~~~^^^^^^
  File "C:\Users\Technomowj\AppData\Local\Programs\Python\Python313\Lib\site-packages\rest_framework\fields.py", line 548, in run_validation
    self.run_validators(value)
    ~~~~~~~~~~~~~~~~~~~^^^^^^^
  File "C:\Users\Technomowj\AppData\Local\Programs\Python\Python313\Lib\site-packages\rest_framework\fields.py", line 560, in run_validators
    validator(value, self)
    ~~~~~~~~~^^^^^^^^^^^^^
  File "C:\Users\Technomowj\AppData\Local\Programs\Python\Python313\Lib\site-packages\rest_framework\validators.py", line 73, in __call__
    if qs_exists(queryset):
       ~~~~~~~~~^^^^^^^^^^
  File "C:\Users\Technomowj\AppData\Local\Programs\Python\Python313\Lib\site-packages\rest_framework\validators.py", line 21, in qs_exists
    return queryset.exists()
           ~~~~~~~~~~~~~~~^^
  File "C:\Users\Technomowj\AppData\Local\Programs\Python\Python313\Lib\site-packages\django\db\models\query.py", line 1241, in exists
    return self.query.has_results(using=self.db)
           ~~~~~~~~~~~~~~~~~~~~~~^^^^^^^^^^^^^^^
  File "C:\Users\Technomowj\AppData\Local\Programs\Python\Python313\Lib\site-packages\django\db\models\sql\query.py", line 598, in has_results
    return compiler.has_results()
           ~~~~~~~~~~~~~~~~~~~~^^
  File "C:\Users\Technomowj\AppData\Local\Programs\Python\Python313\Lib\site-packages\django\db\models\sql\compiler.py", line 1530, in has_results
    return bool(self.execute_sql(SINGLE))
                ~~~~~~~~~~~~~~~~^^^^^^^^
  File "C:\Users\Technomowj\AppData\Local\Programs\Python\Python313\Lib\site-packages\django\db\models\sql\compiler.py", line 1562, in execute_sql
    cursor.execute(sql, params)
    ~~~~~~~~~~~~~~^^^^^^^^^^^^^
  File "C:\Users\Technomowj\AppData\Local\Programs\Python\Python313\Lib\site-packages\django\db\backends\utils.py", line 102, in execute
    return super().execute(sql, params)
           ~~~~~~~~~~~~~~~^^^^^^^^^^^^^
  File "C:\Users\Technomowj\AppData\Local\Programs\Python\Python313\Lib\site-packages\django\db\backends\utils.py", line 67, in execute
    return self._execute_with_wrappers(
           ~~~~~~~~~~~~~~~~~~~~~~~~~~~^
        sql, params, many=False, executor=self._execute
        ^^^^^^^^^^^^^^^^^^^^^^^^^^^^^^^^^^^^^^^^^^^^^^^
    )
    ^
  File "C:\Users\Technomowj\AppData\Local\Programs\Python\Python313\Lib\site-packages\django\db\backends\utils.py", line 80, in _execute_with_wrappers
    return executor(sql, params, many, context)
  File "C:\Users\Technomowj\AppData\Local\Programs\Python\Python313\Lib\site-packages\django\db\backends\utils.py", line 84, in _execute
    with self.db.wrap_database_errors:
         ^^^^^^^^^^^^^^^^^^^^^^^^^^^^
  File "C:\Users\Technomowj\AppData\Local\Programs\Python\Python313\Lib\site-packages\django\db\utils.py", line 91, in __exit__
    raise dj_exc_value.with_traceback(traceback) from exc_value
  File "C:\Users\Technomowj\AppData\Local\Programs\Python\Python313\Lib\site-packages\django\db\backends\utils.py", line 89, in _execute
    return self.cursor.execute(sql, params)
           ~~~~~~~~~~~~~~~~~~~^^^^^^^^^^^^^
  File "C:\Users\Technomowj\AppData\Local\Programs\Python\Python313\Lib\site-packages\django\db\backends\sqlite3\base.py", line 328, in execute
    return super().execute(query, params)
           ~~~~~~~~~~~~~~~^^^^^^^^^^^^^^^
django.db.utils.OperationalError: no such table: game_user
WARNING 2025-08-07 01:36:10,373 log 17756 10872 Not Found: /.well-known/appspecific/com.chrome.devtools.json
INFO 2025-08-07 01:38:39,740 autoreload 12992 32060 Watching for file changes with StatReloader
WARNING 2025-08-07 01:40:52,159 log 12992 13448 Unauthorized: /api/rooms/b1befc26-6ecd-4f9b-8859-0e2f3bcd5280/activity/
WARNING 2025-08-07 01:40:53,631 log 12992 13448 Unauthorized: /api/rooms/b1befc26-6ecd-4f9b-8859-0e2f3bcd5280/activity/
WARNING 2025-08-07 01:40:55,632 log 12992 13448 Unauthorized: /api/rooms/b1befc26-6ecd-4f9b-8859-0e2f3bcd5280/activity/
WARNING 2025-08-07 01:40:57,622 log 12992 13448 Unauthorized: /api/rooms/b1befc26-6ecd-4f9b-8859-0e2f3bcd5280/activity/
WARNING 2025-08-07 01:40:59,625 log 12992 13448 Unauthorized: /api/rooms/b1befc26-6ecd-4f9b-8859-0e2f3bcd5280/activity/
WARNING 2025-08-07 01:41:31,631 log 12992 24736 Unauthorized: /api/rooms/b1befc26-6ecd-4f9b-8859-0e2f3bcd5280/activity/
WARNING 2025-08-07 01:41:33,623 log 12992 24736 Unauthorized: /api/rooms/b1befc26-6ecd-4f9b-8859-0e2f3bcd5280/activity/
WARNING 2025-08-07 01:41:35,623 log 12992 24736 Unauthorized: /api/rooms/b1befc26-6ecd-4f9b-8859-0e2f3bcd5280/activity/
WARNING 2025-08-07 01:41:37,631 log 12992 24736 Unauthorized: /api/rooms/b1befc26-6ecd-4f9b-8859-0e2f3bcd5280/activity/
WARNING 2025-08-07 01:41:39,633 log 12992 24736 Unauthorized: /api/rooms/b1befc26-6ecd-4f9b-8859-0e2f3bcd5280/activity/
WARNING 2025-08-07 01:41:41,620 log 12992 24736 Unauthorized: /api/rooms/b1befc26-6ecd-4f9b-8859-0e2f3bcd5280/activity/
WARNING 2025-08-07 01:41:43,634 log 12992 24736 Unauthorized: /api/rooms/b1befc26-6ecd-4f9b-8859-0e2f3bcd5280/activity/
WARNING 2025-08-07 01:41:45,627 log 12992 24736 Unauthorized: /api/rooms/b1befc26-6ecd-4f9b-8859-0e2f3bcd5280/activity/
WARNING 2025-08-07 01:41:47,622 log 12992 24736 Unauthorized: /api/rooms/b1befc26-6ecd-4f9b-8859-0e2f3bcd5280/activity/
WARNING 2025-08-07 01:41:49,622 log 12992 24736 Unauthorized: /api/rooms/b1befc26-6ecd-4f9b-8859-0e2f3bcd5280/activity/
WARNING 2025-08-07 01:41:51,635 log 12992 24736 Unauthorized: /api/rooms/b1befc26-6ecd-4f9b-8859-0e2f3bcd5280/activity/
WARNING 2025-08-07 01:41:53,634 log 12992 24736 Unauthorized: /api/rooms/b1befc26-6ecd-4f9b-8859-0e2f3bcd5280/activity/
WARNING 2025-08-07 01:41:55,635 log 12992 24736 Unauthorized: /api/rooms/b1befc26-6ecd-4f9b-8859-0e2f3bcd5280/activity/
INFO 2025-08-07 01:44:46,106 autoreload 15624 7780 Watching for file changes with StatReloader
INFO 2025-08-07 01:45:16,442 autoreload 15624 7780 D:\code\10\numberhunt\settings.py changed, reloading.
INFO 2025-08-07 01:45:19,345 autoreload 32468 16340 Watching for file changes with StatReloader
INFO 2025-08-07 01:47:16,779 autoreload 32468 16340 D:\code\10\numberhunt\settings.py changed, reloading.
INFO 2025-08-07 01:47:17,575 autoreload 20920 14084 Watching for file changes with StatReloader
WARNING 2025-08-07 01:47:45,182 log 20920 29044 Not Found: /favicon.ico
WARNING 2025-08-07 01:48:13,200 log 20920 6792 Not Found: /favicon.ico
WARNING 2025-08-07 01:50:15,664 log 20920 27464 Not Found: /favicon.ico
INFO 2025-08-07 02:00:26,762 autoreload 13856 14372 Watching for file changes with StatReloader
ERROR 2025-08-07 02:01:01,397 log 13856 27736 Internal Server Error: /api/rooms/create/
Traceback (most recent call last):
  File "C:\Users\Technomowj\AppData\Local\Programs\Python\Python313\Lib\site-packages\django\db\backends\utils.py", line 89, in _execute
    return self.cursor.execute(sql, params)
           ~~~~~~~~~~~~~~~~~~~^^^^^^^^^^^^^
  File "C:\Users\Technomowj\AppData\Local\Programs\Python\Python313\Lib\site-packages\django\db\backends\sqlite3\base.py", line 328, in execute
    return super().execute(query, params)
           ~~~~~~~~~~~~~~~^^^^^^^^^^^^^^^
sqlite3.IntegrityError: UNIQUE constraint failed: game_gameroom.room_code

The above exception was the direct cause of the following exception:

Traceback (most recent call last):
  File "C:\Users\Technomowj\AppData\Local\Programs\Python\Python313\Lib\site-packages\django\core\handlers\exception.py", line 55, in inner
    response = get_response(request)
  File "C:\Users\Technomowj\AppData\Local\Programs\Python\Python313\Lib\site-packages\django\core\handlers\base.py", line 197, in _get_response
    response = wrapped_callback(request, *callback_args, **callback_kwargs)
  File "C:\Users\Technomowj\AppData\Local\Programs\Python\Python313\Lib\site-packages\django\views\decorators\csrf.py", line 56, in wrapper_view
    return view_func(*args, **kwargs)
  File "C:\Users\Technomowj\AppData\Local\Programs\Python\Python313\Lib\site-packages\django\views\generic\base.py", line 104, in view
    return self.dispatch(request, *args, **kwargs)
           ~~~~~~~~~~~~~^^^^^^^^^^^^^^^^^^^^^^^^^^
  File "C:\Users\Technomowj\AppData\Local\Programs\Python\Python313\Lib\site-packages\rest_framework\views.py", line 509, in dispatch
    response = self.handle_exception(exc)
  File "C:\Users\Technomowj\AppData\Local\Programs\Python\Python313\Lib\site-packages\rest_framework\views.py", line 469, in handle_exception
    self.raise_uncaught_exception(exc)
    ~~~~~~~~~~~~~~~~~~~~~~~~~~~~~^^^^^
  File "C:\Users\Technomowj\AppData\Local\Programs\Python\Python313\Lib\site-packages\rest_framework\views.py", line 480, in raise_uncaught_exception
    raise exc
  File "C:\Users\Technomowj\AppData\Local\Programs\Python\Python313\Lib\site-packages\rest_framework\views.py", line 506, in dispatch
    response = handler(request, *args, **kwargs)
  File "C:\Users\Technomowj\AppData\Local\Programs\Python\Python313\Lib\site-packages\rest_framework\decorators.py", line 50, in handler
    return func(*args, **kwargs)
  File "D:\code\10\game\views.py", line 165, in create_room
    room = serializer.save(host=request.user)
  File "C:\Users\Technomowj\AppData\Local\Programs\Python\Python313\Lib\site-packages\rest_framework\serializers.py", line 212, in save
    self.instance = self.create(validated_data)
                    ~~~~~~~~~~~^^^^^^^^^^^^^^^^
  File "C:\Users\Technomowj\AppData\Local\Programs\Python\Python313\Lib\site-packages\rest_framework\serializers.py", line 962, in create
    instance = ModelClass._default_manager.create(**validated_data)
  File "C:\Users\Technomowj\AppData\Local\Programs\Python\Python313\Lib\site-packages\django\db\models\manager.py", line 87, in manager_method
    return getattr(self.get_queryset(), name)(*args, **kwargs)
           ~~~~~~~~~~~~~~~~~~~~~~~~~~~~~~~~~~^^^^^^^^^^^^^^^^^
  File "C:\Users\Technomowj\AppData\Local\Programs\Python\Python313\Lib\site-packages\django\db\models\query.py", line 658, in create
    obj.save(force_insert=True, using=self.db)
    ~~~~~~~~^^^^^^^^^^^^^^^^^^^^^^^^^^^^^^^^^^
  File "D:\code\10\game\models.py", line 104, in save
    super().save(*args, **kwargs)
    ~~~~~~~~~~~~^^^^^^^^^^^^^^^^^
  File "C:\Users\Technomowj\AppData\Local\Programs\Python\Python313\Lib\site-packages\django\db\models\base.py", line 814, in save
    self.save_base(
    ~~~~~~~~~~~~~~^
        using=using,
        ^^^^^^^^^^^^
    ...<2 lines>...
        update_fields=update_fields,
        ^^^^^^^^^^^^^^^^^^^^^^^^^^^^
    )
    ^
  File "C:\Users\Technomowj\AppData\Local\Programs\Python\Python313\Lib\site-packages\django\db\models\base.py", line 877, in save_base
    updated = self._save_table(
        raw,
    ...<4 lines>...
        update_fields,
    )
  File "C:\Users\Technomowj\AppData\Local\Programs\Python\Python313\Lib\site-packages\django\db\models\base.py", line 1020, in _save_table
    results = self._do_insert(
        cls._base_manager, using, fields, returning_fields, raw
    )
  File "C:\Users\Technomowj\AppData\Local\Programs\Python\Python313\Lib\site-packages\django\db\models\base.py", line 1061, in _do_insert
    return manager._insert(
           ~~~~~~~~~~~~~~~^
        [self],
        ^^^^^^^
    ...<3 lines>...
        raw=raw,
        ^^^^^^^^
    )
    ^
  File "C:\Users\Technomowj\AppData\Local\Programs\Python\Python313\Lib\site-packages\django\db\models\manager.py", line 87, in manager_method
    return getattr(self.get_queryset(), name)(*args, **kwargs)
           ~~~~~~~~~~~~~~~~~~~~~~~~~~~~~~~~~~^^^^^^^^^^^^^^^^^
  File "C:\Users\Technomowj\AppData\Local\Programs\Python\Python313\Lib\site-packages\django\db\models\query.py", line 1805, in _insert
    return query.get_compiler(using=using).execute_sql(returning_fields)
           ~~~~~~~~~~~~~~~~~~~~~~~~~~~~~~~~~~~~~~~~~~~^^^^^^^^^^^^^^^^^^
  File "C:\Users\Technomowj\AppData\Local\Programs\Python\Python313\Lib\site-packages\django\db\models\sql\compiler.py", line 1822, in execute_sql
    cursor.execute(sql, params)
    ~~~~~~~~~~~~~~^^^^^^^^^^^^^
  File "C:\Users\Technomowj\AppData\Local\Programs\Python\Python313\Lib\site-packages\django\db\backends\utils.py", line 102, in execute
    return super().execute(sql, params)
           ~~~~~~~~~~~~~~~^^^^^^^^^^^^^
  File "C:\Users\Technomowj\AppData\Local\Programs\Python\Python313\Lib\site-packages\django\db\backends\utils.py", line 67, in execute
    return self._execute_with_wrappers(
           ~~~~~~~~~~~~~~~~~~~~~~~~~~~^
        sql, params, many=False, executor=self._execute
        ^^^^^^^^^^^^^^^^^^^^^^^^^^^^^^^^^^^^^^^^^^^^^^^
    )
    ^
  File "C:\Users\Technomowj\AppData\Local\Programs\Python\Python313\Lib\site-packages\django\db\backends\utils.py", line 80, in _execute_with_wrappers
    return executor(sql, params, many, context)
  File "C:\Users\Technomowj\AppData\Local\Programs\Python\Python313\Lib\site-packages\django\db\backends\utils.py", line 84, in _execute
    with self.db.wrap_database_errors:
         ^^^^^^^^^^^^^^^^^^^^^^^^^^^^
  File "C:\Users\Technomowj\AppData\Local\Programs\Python\Python313\Lib\site-packages\django\db\utils.py", line 91, in __exit__
    raise dj_exc_value.with_traceback(traceback) from exc_value
  File "C:\Users\Technomowj\AppData\Local\Programs\Python\Python313\Lib\site-packages\django\db\backends\utils.py", line 89, in _execute
    return self.cursor.execute(sql, params)
           ~~~~~~~~~~~~~~~~~~~^^^^^^^^^^^^^
  File "C:\Users\Technomowj\AppData\Local\Programs\Python\Python313\Lib\site-packages\django\db\backends\sqlite3\base.py", line 328, in execute
    return super().execute(query, params)
           ~~~~~~~~~~~~~~~^^^^^^^^^^^^^^^
django.db.utils.IntegrityError: UNIQUE constraint failed: game_gameroom.room_code
WARNING 2025-08-07 02:01:06,965 log 13856 27736 Not Found: /.well-known/appspecific/com.chrome.devtools.json
ERROR 2025-08-07 02:01:11,128 log 13856 27736 Internal Server Error: /api/rooms/create/
Traceback (most recent call last):
  File "C:\Users\Technomowj\AppData\Local\Programs\Python\Python313\Lib\site-packages\django\db\backends\utils.py", line 89, in _execute
    return self.cursor.execute(sql, params)
           ~~~~~~~~~~~~~~~~~~~^^^^^^^^^^^^^
  File "C:\Users\Technomowj\AppData\Local\Programs\Python\Python313\Lib\site-packages\django\db\backends\sqlite3\base.py", line 328, in execute
    return super().execute(query, params)
           ~~~~~~~~~~~~~~~^^^^^^^^^^^^^^^
sqlite3.IntegrityError: UNIQUE constraint failed: game_gameroom.room_code

The above exception was the direct cause of the following exception:

Traceback (most recent call last):
  File "C:\Users\Technomowj\AppData\Local\Programs\Python\Python313\Lib\site-packages\django\core\handlers\exception.py", line 55, in inner
    response = get_response(request)
  File "C:\Users\Technomowj\AppData\Local\Programs\Python\Python313\Lib\site-packages\django\core\handlers\base.py", line 197, in _get_response
    response = wrapped_callback(request, *callback_args, **callback_kwargs)
  File "C:\Users\Technomowj\AppData\Local\Programs\Python\Python313\Lib\site-packages\django\views\decorators\csrf.py", line 56, in wrapper_view
    return view_func(*args, **kwargs)
  File "C:\Users\Technomowj\AppData\Local\Programs\Python\Python313\Lib\site-packages\django\views\generic\base.py", line 104, in view
    return self.dispatch(request, *args, **kwargs)
           ~~~~~~~~~~~~~^^^^^^^^^^^^^^^^^^^^^^^^^^
  File "C:\Users\Technomowj\AppData\Local\Programs\Python\Python313\Lib\site-packages\rest_framework\views.py", line 509, in dispatch
    response = self.handle_exception(exc)
  File "C:\Users\Technomowj\AppData\Local\Programs\Python\Python313\Lib\site-packages\rest_framework\views.py", line 469, in handle_exception
    self.raise_uncaught_exception(exc)
    ~~~~~~~~~~~~~~~~~~~~~~~~~~~~~^^^^^
  File "C:\Users\Technomowj\AppData\Local\Programs\Python\Python313\Lib\site-packages\rest_framework\views.py", line 480, in raise_uncaught_exception
    raise exc
  File "C:\Users\Technomowj\AppData\Local\Programs\Python\Python313\Lib\site-packages\rest_framework\views.py", line 506, in dispatch
    response = handler(request, *args, **kwargs)
  File "C:\Users\Technomowj\AppData\Local\Programs\Python\Python313\Lib\site-packages\rest_framework\decorators.py", line 50, in handler
    return func(*args, **kwargs)
  File "D:\code\10\game\views.py", line 165, in create_room
    room = serializer.save(host=request.user)
  File "C:\Users\Technomowj\AppData\Local\Programs\Python\Python313\Lib\site-packages\rest_framework\serializers.py", line 212, in save
    self.instance = self.create(validated_data)
                    ~~~~~~~~~~~^^^^^^^^^^^^^^^^
  File "C:\Users\Technomowj\AppData\Local\Programs\Python\Python313\Lib\site-packages\rest_framework\serializers.py", line 962, in create
    instance = ModelClass._default_manager.create(**validated_data)
  File "C:\Users\Technomowj\AppData\Local\Programs\Python\Python313\Lib\site-packages\django\db\models\manager.py", line 87, in manager_method
    return getattr(self.get_queryset(), name)(*args, **kwargs)
           ~~~~~~~~~~~~~~~~~~~~~~~~~~~~~~~~~~^^^^^^^^^^^^^^^^^
  File "C:\Users\Technomowj\AppData\Local\Programs\Python\Python313\Lib\site-packages\django\db\models\query.py", line 658, in create
    obj.save(force_insert=True, using=self.db)
    ~~~~~~~~^^^^^^^^^^^^^^^^^^^^^^^^^^^^^^^^^^
  File "D:\code\10\game\models.py", line 104, in save
    super().save(*args, **kwargs)
    ~~~~~~~~~~~~^^^^^^^^^^^^^^^^^
  File "C:\Users\Technomowj\AppData\Local\Programs\Python\Python313\Lib\site-packages\django\db\models\base.py", line 814, in save
    self.save_base(
    ~~~~~~~~~~~~~~^
        using=using,
        ^^^^^^^^^^^^
    ...<2 lines>...
        update_fields=update_fields,
        ^^^^^^^^^^^^^^^^^^^^^^^^^^^^
    )
    ^
  File "C:\Users\Technomowj\AppData\Local\Programs\Python\Python313\Lib\site-packages\django\db\models\base.py", line 877, in save_base
    updated = self._save_table(
        raw,
    ...<4 lines>...
        update_fields,
    )
  File "C:\Users\Technomowj\AppData\Local\Programs\Python\Python313\Lib\site-packages\django\db\models\base.py", line 1020, in _save_table
    results = self._do_insert(
        cls._base_manager, using, fields, returning_fields, raw
    )
  File "C:\Users\Technomowj\AppData\Local\Programs\Python\Python313\Lib\site-packages\django\db\models\base.py", line 1061, in _do_insert
    return manager._insert(
           ~~~~~~~~~~~~~~~^
        [self],
        ^^^^^^^
    ...<3 lines>...
        raw=raw,
        ^^^^^^^^
    )
    ^
  File "C:\Users\Technomowj\AppData\Local\Programs\Python\Python313\Lib\site-packages\django\db\models\manager.py", line 87, in manager_method
    return getattr(self.get_queryset(), name)(*args, **kwargs)
           ~~~~~~~~~~~~~~~~~~~~~~~~~~~~~~~~~~^^^^^^^^^^^^^^^^^
  File "C:\Users\Technomowj\AppData\Local\Programs\Python\Python313\Lib\site-packages\django\db\models\query.py", line 1805, in _insert
    return query.get_compiler(using=using).execute_sql(returning_fields)
           ~~~~~~~~~~~~~~~~~~~~~~~~~~~~~~~~~~~~~~~~~~~^^^^^^^^^^^^^^^^^^
  File "C:\Users\Technomowj\AppData\Local\Programs\Python\Python313\Lib\site-packages\django\db\models\sql\compiler.py", line 1822, in execute_sql
    cursor.execute(sql, params)
    ~~~~~~~~~~~~~~^^^^^^^^^^^^^
  File "C:\Users\Technomowj\AppData\Local\Programs\Python\Python313\Lib\site-packages\django\db\backends\utils.py", line 102, in execute
    return super().execute(sql, params)
           ~~~~~~~~~~~~~~~^^^^^^^^^^^^^
  File "C:\Users\Technomowj\AppData\Local\Programs\Python\Python313\Lib\site-packages\django\db\backends\utils.py", line 67, in execute
    return self._execute_with_wrappers(
           ~~~~~~~~~~~~~~~~~~~~~~~~~~~^
        sql, params, many=False, executor=self._execute
        ^^^^^^^^^^^^^^^^^^^^^^^^^^^^^^^^^^^^^^^^^^^^^^^
    )
    ^
  File "C:\Users\Technomowj\AppData\Local\Programs\Python\Python313\Lib\site-packages\django\db\backends\utils.py", line 80, in _execute_with_wrappers
    return executor(sql, params, many, context)
  File "C:\Users\Technomowj\AppData\Local\Programs\Python\Python313\Lib\site-packages\django\db\backends\utils.py", line 84, in _execute
    with self.db.wrap_database_errors:
         ^^^^^^^^^^^^^^^^^^^^^^^^^^^^
  File "C:\Users\Technomowj\AppData\Local\Programs\Python\Python313\Lib\site-packages\django\db\utils.py", line 91, in __exit__
    raise dj_exc_value.with_traceback(traceback) from exc_value
  File "C:\Users\Technomowj\AppData\Local\Programs\Python\Python313\Lib\site-packages\django\db\backends\utils.py", line 89, in _execute
    return self.cursor.execute(sql, params)
           ~~~~~~~~~~~~~~~~~~~^^^^^^^^^^^^^
  File "C:\Users\Technomowj\AppData\Local\Programs\Python\Python313\Lib\site-packages\django\db\backends\sqlite3\base.py", line 328, in execute
    return super().execute(query, params)
           ~~~~~~~~~~~~~~~^^^^^^^^^^^^^^^
django.db.utils.IntegrityError: UNIQUE constraint failed: game_gameroom.room_code
INFO 2025-08-07 02:02:27,724 autoreload 13856 14372 D:\code\10\game\models.py changed, reloading.
INFO 2025-08-07 02:02:28,387 autoreload 15028 21640 Watching for file changes with StatReloader
INFO 2025-08-07 02:02:53,018 autoreload 25492 27980 Watching for file changes with StatReloader
ERROR 2025-08-07 02:02:59,164 log 25492 27080 Internal Server Error: /api/rooms/create/
Traceback (most recent call last):
  File "C:\Users\Technomowj\AppData\Local\Programs\Python\Python313\Lib\site-packages\django\db\backends\utils.py", line 89, in _execute
    return self.cursor.execute(sql, params)
           ~~~~~~~~~~~~~~~~~~~^^^^^^^^^^^^^
  File "C:\Users\Technomowj\AppData\Local\Programs\Python\Python313\Lib\site-packages\django\db\backends\sqlite3\base.py", line 328, in execute
    return super().execute(query, params)
           ~~~~~~~~~~~~~~~^^^^^^^^^^^^^^^
sqlite3.IntegrityError: UNIQUE constraint failed: game_gameroom.room_code

The above exception was the direct cause of the following exception:

Traceback (most recent call last):
  File "C:\Users\Technomowj\AppData\Local\Programs\Python\Python313\Lib\site-packages\django\core\handlers\exception.py", line 55, in inner
    response = get_response(request)
  File "C:\Users\Technomowj\AppData\Local\Programs\Python\Python313\Lib\site-packages\django\core\handlers\base.py", line 197, in _get_response
    response = wrapped_callback(request, *callback_args, **callback_kwargs)
  File "C:\Users\Technomowj\AppData\Local\Programs\Python\Python313\Lib\site-packages\django\views\decorators\csrf.py", line 56, in wrapper_view
    return view_func(*args, **kwargs)
  File "C:\Users\Technomowj\AppData\Local\Programs\Python\Python313\Lib\site-packages\django\views\generic\base.py", line 104, in view
    return self.dispatch(request, *args, **kwargs)
           ~~~~~~~~~~~~~^^^^^^^^^^^^^^^^^^^^^^^^^^
  File "C:\Users\Technomowj\AppData\Local\Programs\Python\Python313\Lib\site-packages\rest_framework\views.py", line 509, in dispatch
    response = self.handle_exception(exc)
  File "C:\Users\Technomowj\AppData\Local\Programs\Python\Python313\Lib\site-packages\rest_framework\views.py", line 469, in handle_exception
    self.raise_uncaught_exception(exc)
    ~~~~~~~~~~~~~~~~~~~~~~~~~~~~~^^^^^
  File "C:\Users\Technomowj\AppData\Local\Programs\Python\Python313\Lib\site-packages\rest_framework\views.py", line 480, in raise_uncaught_exception
    raise exc
  File "C:\Users\Technomowj\AppData\Local\Programs\Python\Python313\Lib\site-packages\rest_framework\views.py", line 506, in dispatch
    response = handler(request, *args, **kwargs)
  File "C:\Users\Technomowj\AppData\Local\Programs\Python\Python313\Lib\site-packages\rest_framework\decorators.py", line 50, in handler
    return func(*args, **kwargs)
  File "D:\code\10\game\views.py", line 165, in create_room
    room = serializer.save(host=request.user)
  File "C:\Users\Technomowj\AppData\Local\Programs\Python\Python313\Lib\site-packages\rest_framework\serializers.py", line 212, in save
    self.instance = self.create(validated_data)
                    ~~~~~~~~~~~^^^^^^^^^^^^^^^^
  File "C:\Users\Technomowj\AppData\Local\Programs\Python\Python313\Lib\site-packages\rest_framework\serializers.py", line 962, in create
    instance = ModelClass._default_manager.create(**validated_data)
  File "C:\Users\Technomowj\AppData\Local\Programs\Python\Python313\Lib\site-packages\django\db\models\manager.py", line 87, in manager_method
    return getattr(self.get_queryset(), name)(*args, **kwargs)
           ~~~~~~~~~~~~~~~~~~~~~~~~~~~~~~~~~~^^^^^^^^^^^^^^^^^
  File "C:\Users\Technomowj\AppData\Local\Programs\Python\Python313\Lib\site-packages\django\db\models\query.py", line 658, in create
    obj.save(force_insert=True, using=self.db)
    ~~~~~~~~^^^^^^^^^^^^^^^^^^^^^^^^^^^^^^^^^^
  File "D:\code\10\game\models.py", line 116, in save
    super().save(*args, **kwargs)
    ~~~~~~~~~~~~^^^^^^^^^^^^^^^^^
  File "C:\Users\Technomowj\AppData\Local\Programs\Python\Python313\Lib\site-packages\django\db\models\base.py", line 814, in save
    self.save_base(
    ~~~~~~~~~~~~~~^
        using=using,
        ^^^^^^^^^^^^
    ...<2 lines>...
        update_fields=update_fields,
        ^^^^^^^^^^^^^^^^^^^^^^^^^^^^
    )
    ^
  File "C:\Users\Technomowj\AppData\Local\Programs\Python\Python313\Lib\site-packages\django\db\models\base.py", line 877, in save_base
    updated = self._save_table(
        raw,
    ...<4 lines>...
        update_fields,
    )
  File "C:\Users\Technomowj\AppData\Local\Programs\Python\Python313\Lib\site-packages\django\db\models\base.py", line 1020, in _save_table
    results = self._do_insert(
        cls._base_manager, using, fields, returning_fields, raw
    )
  File "C:\Users\Technomowj\AppData\Local\Programs\Python\Python313\Lib\site-packages\django\db\models\base.py", line 1061, in _do_insert
    return manager._insert(
           ~~~~~~~~~~~~~~~^
        [self],
        ^^^^^^^
    ...<3 lines>...
        raw=raw,
        ^^^^^^^^
    )
    ^
  File "C:\Users\Technomowj\AppData\Local\Programs\Python\Python313\Lib\site-packages\django\db\models\manager.py", line 87, in manager_method
    return getattr(self.get_queryset(), name)(*args, **kwargs)
           ~~~~~~~~~~~~~~~~~~~~~~~~~~~~~~~~~~^^^^^^^^^^^^^^^^^
  File "C:\Users\Technomowj\AppData\Local\Programs\Python\Python313\Lib\site-packages\django\db\models\query.py", line 1805, in _insert
    return query.get_compiler(using=using).execute_sql(returning_fields)
           ~~~~~~~~~~~~~~~~~~~~~~~~~~~~~~~~~~~~~~~~~~~^^^^^^^^^^^^^^^^^^
  File "C:\Users\Technomowj\AppData\Local\Programs\Python\Python313\Lib\site-packages\django\db\models\sql\compiler.py", line 1822, in execute_sql
    cursor.execute(sql, params)
    ~~~~~~~~~~~~~~^^^^^^^^^^^^^
  File "C:\Users\Technomowj\AppData\Local\Programs\Python\Python313\Lib\site-packages\django\db\backends\utils.py", line 102, in execute
    return super().execute(sql, params)
           ~~~~~~~~~~~~~~~^^^^^^^^^^^^^
  File "C:\Users\Technomowj\AppData\Local\Programs\Python\Python313\Lib\site-packages\django\db\backends\utils.py", line 67, in execute
    return self._execute_with_wrappers(
           ~~~~~~~~~~~~~~~~~~~~~~~~~~~^
        sql, params, many=False, executor=self._execute
        ^^^^^^^^^^^^^^^^^^^^^^^^^^^^^^^^^^^^^^^^^^^^^^^
    )
    ^
  File "C:\Users\Technomowj\AppData\Local\Programs\Python\Python313\Lib\site-packages\django\db\backends\utils.py", line 80, in _execute_with_wrappers
    return executor(sql, params, many, context)
  File "C:\Users\Technomowj\AppData\Local\Programs\Python\Python313\Lib\site-packages\django\db\backends\utils.py", line 84, in _execute
    with self.db.wrap_database_errors:
         ^^^^^^^^^^^^^^^^^^^^^^^^^^^^
  File "C:\Users\Technomowj\AppData\Local\Programs\Python\Python313\Lib\site-packages\django\db\utils.py", line 91, in __exit__
    raise dj_exc_value.with_traceback(traceback) from exc_value
  File "C:\Users\Technomowj\AppData\Local\Programs\Python\Python313\Lib\site-packages\django\db\backends\utils.py", line 89, in _execute
    return self.cursor.execute(sql, params)
           ~~~~~~~~~~~~~~~~~~~^^^^^^^^^^^^^
  File "C:\Users\Technomowj\AppData\Local\Programs\Python\Python313\Lib\site-packages\django\db\backends\sqlite3\base.py", line 328, in execute
    return super().execute(query, params)
           ~~~~~~~~~~~~~~~^^^^^^^^^^^^^^^
django.db.utils.IntegrityError: UNIQUE constraint failed: game_gameroom.room_code
ERROR 2025-08-07 02:03:16,902 log 25492 27080 Internal Server Error: /api/rooms/create/
Traceback (most recent call last):
  File "C:\Users\Technomowj\AppData\Local\Programs\Python\Python313\Lib\site-packages\django\db\backends\utils.py", line 89, in _execute
    return self.cursor.execute(sql, params)
           ~~~~~~~~~~~~~~~~~~~^^^^^^^^^^^^^
  File "C:\Users\Technomowj\AppData\Local\Programs\Python\Python313\Lib\site-packages\django\db\backends\sqlite3\base.py", line 328, in execute
    return super().execute(query, params)
           ~~~~~~~~~~~~~~~^^^^^^^^^^^^^^^
sqlite3.IntegrityError: UNIQUE constraint failed: game_gameroom.room_code

The above exception was the direct cause of the following exception:

Traceback (most recent call last):
  File "C:\Users\Technomowj\AppData\Local\Programs\Python\Python313\Lib\site-packages\django\core\handlers\exception.py", line 55, in inner
    response = get_response(request)
  File "C:\Users\Technomowj\AppData\Local\Programs\Python\Python313\Lib\site-packages\django\core\handlers\base.py", line 197, in _get_response
    response = wrapped_callback(request, *callback_args, **callback_kwargs)
  File "C:\Users\Technomowj\AppData\Local\Programs\Python\Python313\Lib\site-packages\django\views\decorators\csrf.py", line 56, in wrapper_view
    return view_func(*args, **kwargs)
  File "C:\Users\Technomowj\AppData\Local\Programs\Python\Python313\Lib\site-packages\django\views\generic\base.py", line 104, in view
    return self.dispatch(request, *args, **kwargs)
           ~~~~~~~~~~~~~^^^^^^^^^^^^^^^^^^^^^^^^^^
  File "C:\Users\Technomowj\AppData\Local\Programs\Python\Python313\Lib\site-packages\rest_framework\views.py", line 509, in dispatch
    response = self.handle_exception(exc)
  File "C:\Users\Technomowj\AppData\Local\Programs\Python\Python313\Lib\site-packages\rest_framework\views.py", line 469, in handle_exception
    self.raise_uncaught_exception(exc)
    ~~~~~~~~~~~~~~~~~~~~~~~~~~~~~^^^^^
  File "C:\Users\Technomowj\AppData\Local\Programs\Python\Python313\Lib\site-packages\rest_framework\views.py", line 480, in raise_uncaught_exception
    raise exc
  File "C:\Users\Technomowj\AppData\Local\Programs\Python\Python313\Lib\site-packages\rest_framework\views.py", line 506, in dispatch
    response = handler(request, *args, **kwargs)
  File "C:\Users\Technomowj\AppData\Local\Programs\Python\Python313\Lib\site-packages\rest_framework\decorators.py", line 50, in handler
    return func(*args, **kwargs)
  File "D:\code\10\game\views.py", line 165, in create_room
    room = serializer.save(host=request.user)
  File "C:\Users\Technomowj\AppData\Local\Programs\Python\Python313\Lib\site-packages\rest_framework\serializers.py", line 212, in save
    self.instance = self.create(validated_data)
                    ~~~~~~~~~~~^^^^^^^^^^^^^^^^
  File "C:\Users\Technomowj\AppData\Local\Programs\Python\Python313\Lib\site-packages\rest_framework\serializers.py", line 962, in create
    instance = ModelClass._default_manager.create(**validated_data)
  File "C:\Users\Technomowj\AppData\Local\Programs\Python\Python313\Lib\site-packages\django\db\models\manager.py", line 87, in manager_method
    return getattr(self.get_queryset(), name)(*args, **kwargs)
           ~~~~~~~~~~~~~~~~~~~~~~~~~~~~~~~~~~^^^^^^^^^^^^^^^^^
  File "C:\Users\Technomowj\AppData\Local\Programs\Python\Python313\Lib\site-packages\django\db\models\query.py", line 658, in create
    obj.save(force_insert=True, using=self.db)
    ~~~~~~~~^^^^^^^^^^^^^^^^^^^^^^^^^^^^^^^^^^
  File "D:\code\10\game\models.py", line 116, in save
    super().save(*args, **kwargs)
    ~~~~~~~~~~~~^^^^^^^^^^^^^^^^^
  File "C:\Users\Technomowj\AppData\Local\Programs\Python\Python313\Lib\site-packages\django\db\models\base.py", line 814, in save
    self.save_base(
    ~~~~~~~~~~~~~~^
        using=using,
        ^^^^^^^^^^^^
    ...<2 lines>...
        update_fields=update_fields,
        ^^^^^^^^^^^^^^^^^^^^^^^^^^^^
    )
    ^
  File "C:\Users\Technomowj\AppData\Local\Programs\Python\Python313\Lib\site-packages\django\db\models\base.py", line 877, in save_base
    updated = self._save_table(
        raw,
    ...<4 lines>...
        update_fields,
    )
  File "C:\Users\Technomowj\AppData\Local\Programs\Python\Python313\Lib\site-packages\django\db\models\base.py", line 1020, in _save_table
    results = self._do_insert(
        cls._base_manager, using, fields, returning_fields, raw
    )
  File "C:\Users\Technomowj\AppData\Local\Programs\Python\Python313\Lib\site-packages\django\db\models\base.py", line 1061, in _do_insert
    return manager._insert(
           ~~~~~~~~~~~~~~~^
        [self],
        ^^^^^^^
    ...<3 lines>...
        raw=raw,
        ^^^^^^^^
    )
    ^
  File "C:\Users\Technomowj\AppData\Local\Programs\Python\Python313\Lib\site-packages\django\db\models\manager.py", line 87, in manager_method
    return getattr(self.get_queryset(), name)(*args, **kwargs)
           ~~~~~~~~~~~~~~~~~~~~~~~~~~~~~~~~~~^^^^^^^^^^^^^^^^^
  File "C:\Users\Technomowj\AppData\Local\Programs\Python\Python313\Lib\site-packages\django\db\models\query.py", line 1805, in _insert
    return query.get_compiler(using=using).execute_sql(returning_fields)
           ~~~~~~~~~~~~~~~~~~~~~~~~~~~~~~~~~~~~~~~~~~~^^^^^^^^^^^^^^^^^^
  File "C:\Users\Technomowj\AppData\Local\Programs\Python\Python313\Lib\site-packages\django\db\models\sql\compiler.py", line 1822, in execute_sql
    cursor.execute(sql, params)
    ~~~~~~~~~~~~~~^^^^^^^^^^^^^
  File "C:\Users\Technomowj\AppData\Local\Programs\Python\Python313\Lib\site-packages\django\db\backends\utils.py", line 102, in execute
    return super().execute(sql, params)
           ~~~~~~~~~~~~~~~^^^^^^^^^^^^^
  File "C:\Users\Technomowj\AppData\Local\Programs\Python\Python313\Lib\site-packages\django\db\backends\utils.py", line 67, in execute
    return self._execute_with_wrappers(
           ~~~~~~~~~~~~~~~~~~~~~~~~~~~^
        sql, params, many=False, executor=self._execute
        ^^^^^^^^^^^^^^^^^^^^^^^^^^^^^^^^^^^^^^^^^^^^^^^
    )
    ^
  File "C:\Users\Technomowj\AppData\Local\Programs\Python\Python313\Lib\site-packages\django\db\backends\utils.py", line 80, in _execute_with_wrappers
    return executor(sql, params, many, context)
  File "C:\Users\Technomowj\AppData\Local\Programs\Python\Python313\Lib\site-packages\django\db\backends\utils.py", line 84, in _execute
    with self.db.wrap_database_errors:
         ^^^^^^^^^^^^^^^^^^^^^^^^^^^^
  File "C:\Users\Technomowj\AppData\Local\Programs\Python\Python313\Lib\site-packages\django\db\utils.py", line 91, in __exit__
    raise dj_exc_value.with_traceback(traceback) from exc_value
  File "C:\Users\Technomowj\AppData\Local\Programs\Python\Python313\Lib\site-packages\django\db\backends\utils.py", line 89, in _execute
    return self.cursor.execute(sql, params)
           ~~~~~~~~~~~~~~~~~~~^^^^^^^^^^^^^
  File "C:\Users\Technomowj\AppData\Local\Programs\Python\Python313\Lib\site-packages\django\db\backends\sqlite3\base.py", line 328, in execute
    return super().execute(query, params)
           ~~~~~~~~~~~~~~~^^^^^^^^^^^^^^^
django.db.utils.IntegrityError: UNIQUE constraint failed: game_gameroom.room_code
INFO 2025-08-07 02:04:40,319 autoreload 5700 21508 Watching for file changes with StatReloader
ERROR 2025-08-07 02:04:43,694 log 5700 22596 Internal Server Error: /api/rooms/create/
Traceback (most recent call last):
  File "C:\Users\Technomowj\AppData\Local\Programs\Python\Python313\Lib\site-packages\django\db\backends\utils.py", line 89, in _execute
    return self.cursor.execute(sql, params)
           ~~~~~~~~~~~~~~~~~~~^^^^^^^^^^^^^
  File "C:\Users\Technomowj\AppData\Local\Programs\Python\Python313\Lib\site-packages\django\db\backends\sqlite3\base.py", line 328, in execute
    return super().execute(query, params)
           ~~~~~~~~~~~~~~~^^^^^^^^^^^^^^^
sqlite3.IntegrityError: UNIQUE constraint failed: game_gameroom.room_code

The above exception was the direct cause of the following exception:

Traceback (most recent call last):
  File "C:\Users\Technomowj\AppData\Local\Programs\Python\Python313\Lib\site-packages\django\core\handlers\exception.py", line 55, in inner
    response = get_response(request)
  File "C:\Users\Technomowj\AppData\Local\Programs\Python\Python313\Lib\site-packages\django\core\handlers\base.py", line 197, in _get_response
    response = wrapped_callback(request, *callback_args, **callback_kwargs)
  File "C:\Users\Technomowj\AppData\Local\Programs\Python\Python313\Lib\site-packages\django\views\decorators\csrf.py", line 56, in wrapper_view
    return view_func(*args, **kwargs)
  File "C:\Users\Technomowj\AppData\Local\Programs\Python\Python313\Lib\site-packages\django\views\generic\base.py", line 104, in view
    return self.dispatch(request, *args, **kwargs)
           ~~~~~~~~~~~~~^^^^^^^^^^^^^^^^^^^^^^^^^^
  File "C:\Users\Technomowj\AppData\Local\Programs\Python\Python313\Lib\site-packages\rest_framework\views.py", line 509, in dispatch
    response = self.handle_exception(exc)
  File "C:\Users\Technomowj\AppData\Local\Programs\Python\Python313\Lib\site-packages\rest_framework\views.py", line 469, in handle_exception
    self.raise_uncaught_exception(exc)
    ~~~~~~~~~~~~~~~~~~~~~~~~~~~~~^^^^^
  File "C:\Users\Technomowj\AppData\Local\Programs\Python\Python313\Lib\site-packages\rest_framework\views.py", line 480, in raise_uncaught_exception
    raise exc
  File "C:\Users\Technomowj\AppData\Local\Programs\Python\Python313\Lib\site-packages\rest_framework\views.py", line 506, in dispatch
    response = handler(request, *args, **kwargs)
  File "C:\Users\Technomowj\AppData\Local\Programs\Python\Python313\Lib\site-packages\rest_framework\decorators.py", line 50, in handler
    return func(*args, **kwargs)
  File "D:\code\10\game\views.py", line 165, in create_room
    room = serializer.save(host=request.user)
  File "C:\Users\Technomowj\AppData\Local\Programs\Python\Python313\Lib\site-packages\rest_framework\serializers.py", line 212, in save
    self.instance = self.create(validated_data)
                    ~~~~~~~~~~~^^^^^^^^^^^^^^^^
  File "C:\Users\Technomowj\AppData\Local\Programs\Python\Python313\Lib\site-packages\rest_framework\serializers.py", line 962, in create
    instance = ModelClass._default_manager.create(**validated_data)
  File "C:\Users\Technomowj\AppData\Local\Programs\Python\Python313\Lib\site-packages\django\db\models\manager.py", line 87, in manager_method
    return getattr(self.get_queryset(), name)(*args, **kwargs)
           ~~~~~~~~~~~~~~~~~~~~~~~~~~~~~~~~~~^^^^^^^^^^^^^^^^^
  File "C:\Users\Technomowj\AppData\Local\Programs\Python\Python313\Lib\site-packages\django\db\models\query.py", line 658, in create
    obj.save(force_insert=True, using=self.db)
    ~~~~~~~~^^^^^^^^^^^^^^^^^^^^^^^^^^^^^^^^^^
  File "D:\code\10\game\models.py", line 116, in save
    super().save(*args, **kwargs)
    ~~~~~~~~~~~~^^^^^^^^^^^^^^^^^
  File "C:\Users\Technomowj\AppData\Local\Programs\Python\Python313\Lib\site-packages\django\db\models\base.py", line 814, in save
    self.save_base(
    ~~~~~~~~~~~~~~^
        using=using,
        ^^^^^^^^^^^^
    ...<2 lines>...
        update_fields=update_fields,
        ^^^^^^^^^^^^^^^^^^^^^^^^^^^^
    )
    ^
  File "C:\Users\Technomowj\AppData\Local\Programs\Python\Python313\Lib\site-packages\django\db\models\base.py", line 877, in save_base
    updated = self._save_table(
        raw,
    ...<4 lines>...
        update_fields,
    )
  File "C:\Users\Technomowj\AppData\Local\Programs\Python\Python313\Lib\site-packages\django\db\models\base.py", line 1020, in _save_table
    results = self._do_insert(
        cls._base_manager, using, fields, returning_fields, raw
    )
  File "C:\Users\Technomowj\AppData\Local\Programs\Python\Python313\Lib\site-packages\django\db\models\base.py", line 1061, in _do_insert
    return manager._insert(
           ~~~~~~~~~~~~~~~^
        [self],
        ^^^^^^^
    ...<3 lines>...
        raw=raw,
        ^^^^^^^^
    )
    ^
  File "C:\Users\Technomowj\AppData\Local\Programs\Python\Python313\Lib\site-packages\django\db\models\manager.py", line 87, in manager_method
    return getattr(self.get_queryset(), name)(*args, **kwargs)
           ~~~~~~~~~~~~~~~~~~~~~~~~~~~~~~~~~~^^^^^^^^^^^^^^^^^
  File "C:\Users\Technomowj\AppData\Local\Programs\Python\Python313\Lib\site-packages\django\db\models\query.py", line 1805, in _insert
    return query.get_compiler(using=using).execute_sql(returning_fields)
           ~~~~~~~~~~~~~~~~~~~~~~~~~~~~~~~~~~~~~~~~~~~^^^^^^^^^^^^^^^^^^
  File "C:\Users\Technomowj\AppData\Local\Programs\Python\Python313\Lib\site-packages\django\db\models\sql\compiler.py", line 1822, in execute_sql
    cursor.execute(sql, params)
    ~~~~~~~~~~~~~~^^^^^^^^^^^^^
  File "C:\Users\Technomowj\AppData\Local\Programs\Python\Python313\Lib\site-packages\django\db\backends\utils.py", line 102, in execute
    return super().execute(sql, params)
           ~~~~~~~~~~~~~~~^^^^^^^^^^^^^
  File "C:\Users\Technomowj\AppData\Local\Programs\Python\Python313\Lib\site-packages\django\db\backends\utils.py", line 67, in execute
    return self._execute_with_wrappers(
           ~~~~~~~~~~~~~~~~~~~~~~~~~~~^
        sql, params, many=False, executor=self._execute
        ^^^^^^^^^^^^^^^^^^^^^^^^^^^^^^^^^^^^^^^^^^^^^^^
    )
    ^
  File "C:\Users\Technomowj\AppData\Local\Programs\Python\Python313\Lib\site-packages\django\db\backends\utils.py", line 80, in _execute_with_wrappers
    return executor(sql, params, many, context)
  File "C:\Users\Technomowj\AppData\Local\Programs\Python\Python313\Lib\site-packages\django\db\backends\utils.py", line 84, in _execute
    with self.db.wrap_database_errors:
         ^^^^^^^^^^^^^^^^^^^^^^^^^^^^
  File "C:\Users\Technomowj\AppData\Local\Programs\Python\Python313\Lib\site-packages\django\db\utils.py", line 91, in __exit__
    raise dj_exc_value.with_traceback(traceback) from exc_value
  File "C:\Users\Technomowj\AppData\Local\Programs\Python\Python313\Lib\site-packages\django\db\backends\utils.py", line 89, in _execute
    return self.cursor.execute(sql, params)
           ~~~~~~~~~~~~~~~~~~~^^^^^^^^^^^^^
  File "C:\Users\Technomowj\AppData\Local\Programs\Python\Python313\Lib\site-packages\django\db\backends\sqlite3\base.py", line 328, in execute
    return super().execute(query, params)
           ~~~~~~~~~~~~~~~^^^^^^^^^^^^^^^
django.db.utils.IntegrityError: UNIQUE constraint failed: game_gameroom.room_code
WARNING 2025-08-07 02:05:15,629 log 5700 22596 Not Found: /api/rooms/b1befc26-6ecd-4f9b-8859-0e2f3bcd5280/activity/
WARNING 2025-08-07 02:05:17,624 log 5700 22596 Not Found: /api/rooms/b1befc26-6ecd-4f9b-8859-0e2f3bcd5280/activity/
WARNING 2025-08-07 02:05:19,623 log 5700 22596 Not Found: /api/rooms/b1befc26-6ecd-4f9b-8859-0e2f3bcd5280/activity/
INFO 2025-08-07 02:05:29,474 autoreload 24012 7972 Watching for file changes with StatReloader
WARNING 2025-08-07 02:05:30,232 log 24012 9024 Not Found: /api/rooms/b1befc26-6ecd-4f9b-8859-0e2f3bcd5280/activity/
WARNING 2025-08-07 02:05:31,675 log 24012 9024 Not Found: /api/rooms/b1befc26-6ecd-4f9b-8859-0e2f3bcd5280/activity/
WARNING 2025-08-07 02:05:33,636 log 24012 9024 Not Found: /api/rooms/b1befc26-6ecd-4f9b-8859-0e2f3bcd5280/activity/
WARNING 2025-08-07 02:06:16,660 log 24012 9024 Unauthorized: /api/admin/overview-stats/
WARNING 2025-08-07 02:06:26,782 log 24012 24232 Unauthorized: /api/admin/overview-stats/
INFO 2025-08-07 02:10:51,149 autoreload 24012 7972 D:\code\10\game\views.py changed, reloading.
INFO 2025-08-07 02:10:51,903 autoreload 29572 18656 Watching for file changes with StatReloader
INFO 2025-08-07 02:11:04,062 autoreload 29572 18656 D:\code\10\game\urls.py changed, reloading.
INFO 2025-08-07 02:11:04,591 autoreload 11968 18700 Watching for file changes with StatReloader
INFO 2025-08-07 02:11:11,533 autoreload 11968 18700 D:\code\10\game\urls.py changed, reloading.
INFO 2025-08-07 02:11:12,131 autoreload 16304 7948 Watching for file changes with StatReloader
INFO 2025-08-07 02:11:24,941 autoreload 16304 7948 D:\code\10\game\views.py changed, reloading.
INFO 2025-08-07 02:11:25,430 autoreload 18472 12020 Watching for file changes with StatReloader
INFO 2025-08-07 02:13:32,530 autoreload 18472 12020 D:\code\10\game\urls.py changed, reloading.
INFO 2025-08-07 02:13:33,048 autoreload 5620 14528 Watching for file changes with StatReloader
INFO 2025-08-07 02:14:05,261 autoreload 5620 14528 D:\code\10\game\views.py changed, reloading.
INFO 2025-08-07 02:14:05,994 autoreload 27372 19912 Watching for file changes with StatReloader
INFO 2025-08-07 02:15:02,987 autoreload 13304 5720 Watching for file changes with StatReloader
INFO 2025-08-07 02:16:45,846 autoreload 1200 10904 Watching for file changes with StatReloader
WARNING 2025-08-07 02:16:46,659 log 1200 32708 Unauthorized: /api/rooms/b1befc26-6ecd-4f9b-8859-0e2f3bcd5280/activity/
WARNING 2025-08-07 02:16:48,979 log 1200 10528 Not Found: /favicon.ico
WARNING 2025-08-07 02:17:00,094 log 1200 19480 Not Found: /favicon.ico
WARNING 2025-08-07 02:17:46,162 log 1200 32708 Forbidden: /api/rooms/b1befc26-6ecd-4f9b-8859-0e2f3bcd5280/activity/
ERROR 2025-08-07 02:17:59,452 log 1200 26492 Internal Server Error: /api/rooms/create/
Traceback (most recent call last):
  File "C:\Users\Technomowj\AppData\Local\Programs\Python\Python313\Lib\site-packages\django\db\backends\utils.py", line 89, in _execute
    return self.cursor.execute(sql, params)
           ~~~~~~~~~~~~~~~~~~~^^^^^^^^^^^^^
  File "C:\Users\Technomowj\AppData\Local\Programs\Python\Python313\Lib\site-packages\django\db\backends\sqlite3\base.py", line 328, in execute
    return super().execute(query, params)
           ~~~~~~~~~~~~~~~^^^^^^^^^^^^^^^
sqlite3.IntegrityError: UNIQUE constraint failed: game_gameroom.room_code

The above exception was the direct cause of the following exception:

Traceback (most recent call last):
  File "C:\Users\Technomowj\AppData\Local\Programs\Python\Python313\Lib\site-packages\django\core\handlers\exception.py", line 55, in inner
    response = get_response(request)
  File "C:\Users\Technomowj\AppData\Local\Programs\Python\Python313\Lib\site-packages\django\core\handlers\base.py", line 197, in _get_response
    response = wrapped_callback(request, *callback_args, **callback_kwargs)
  File "C:\Users\Technomowj\AppData\Local\Programs\Python\Python313\Lib\site-packages\django\views\decorators\csrf.py", line 56, in wrapper_view
    return view_func(*args, **kwargs)
  File "C:\Users\Technomowj\AppData\Local\Programs\Python\Python313\Lib\site-packages\django\views\generic\base.py", line 104, in view
    return self.dispatch(request, *args, **kwargs)
           ~~~~~~~~~~~~~^^^^^^^^^^^^^^^^^^^^^^^^^^
  File "C:\Users\Technomowj\AppData\Local\Programs\Python\Python313\Lib\site-packages\rest_framework\views.py", line 509, in dispatch
    response = self.handle_exception(exc)
  File "C:\Users\Technomowj\AppData\Local\Programs\Python\Python313\Lib\site-packages\rest_framework\views.py", line 469, in handle_exception
    self.raise_uncaught_exception(exc)
    ~~~~~~~~~~~~~~~~~~~~~~~~~~~~~^^^^^
  File "C:\Users\Technomowj\AppData\Local\Programs\Python\Python313\Lib\site-packages\rest_framework\views.py", line 480, in raise_uncaught_exception
    raise exc
  File "C:\Users\Technomowj\AppData\Local\Programs\Python\Python313\Lib\site-packages\rest_framework\views.py", line 506, in dispatch
    response = handler(request, *args, **kwargs)
  File "C:\Users\Technomowj\AppData\Local\Programs\Python\Python313\Lib\site-packages\rest_framework\decorators.py", line 50, in handler
    return func(*args, **kwargs)
  File "D:\code\10\game\views.py", line 165, in create_room
    room = serializer.save(host=request.user)
  File "C:\Users\Technomowj\AppData\Local\Programs\Python\Python313\Lib\site-packages\rest_framework\serializers.py", line 212, in save
    self.instance = self.create(validated_data)
                    ~~~~~~~~~~~^^^^^^^^^^^^^^^^
  File "C:\Users\Technomowj\AppData\Local\Programs\Python\Python313\Lib\site-packages\rest_framework\serializers.py", line 962, in create
    instance = ModelClass._default_manager.create(**validated_data)
  File "C:\Users\Technomowj\AppData\Local\Programs\Python\Python313\Lib\site-packages\django\db\models\manager.py", line 87, in manager_method
    return getattr(self.get_queryset(), name)(*args, **kwargs)
           ~~~~~~~~~~~~~~~~~~~~~~~~~~~~~~~~~~^^^^^^^^^^^^^^^^^
  File "C:\Users\Technomowj\AppData\Local\Programs\Python\Python313\Lib\site-packages\django\db\models\query.py", line 658, in create
    obj.save(force_insert=True, using=self.db)
    ~~~~~~~~^^^^^^^^^^^^^^^^^^^^^^^^^^^^^^^^^^
  File "D:\code\10\game\models.py", line 116, in save
    super().save(*args, **kwargs)
    ~~~~~~~~~~~~^^^^^^^^^^^^^^^^^
  File "C:\Users\Technomowj\AppData\Local\Programs\Python\Python313\Lib\site-packages\django\db\models\base.py", line 814, in save
    self.save_base(
    ~~~~~~~~~~~~~~^
        using=using,
        ^^^^^^^^^^^^
    ...<2 lines>...
        update_fields=update_fields,
        ^^^^^^^^^^^^^^^^^^^^^^^^^^^^
    )
    ^
  File "C:\Users\Technomowj\AppData\Local\Programs\Python\Python313\Lib\site-packages\django\db\models\base.py", line 877, in save_base
    updated = self._save_table(
        raw,
    ...<4 lines>...
        update_fields,
    )
  File "C:\Users\Technomowj\AppData\Local\Programs\Python\Python313\Lib\site-packages\django\db\models\base.py", line 1020, in _save_table
    results = self._do_insert(
        cls._base_manager, using, fields, returning_fields, raw
    )
  File "C:\Users\Technomowj\AppData\Local\Programs\Python\Python313\Lib\site-packages\django\db\models\base.py", line 1061, in _do_insert
    return manager._insert(
           ~~~~~~~~~~~~~~~^
        [self],
        ^^^^^^^
    ...<3 lines>...
        raw=raw,
        ^^^^^^^^
    )
    ^
  File "C:\Users\Technomowj\AppData\Local\Programs\Python\Python313\Lib\site-packages\django\db\models\manager.py", line 87, in manager_method
    return getattr(self.get_queryset(), name)(*args, **kwargs)
           ~~~~~~~~~~~~~~~~~~~~~~~~~~~~~~~~~~^^^^^^^^^^^^^^^^^
  File "C:\Users\Technomowj\AppData\Local\Programs\Python\Python313\Lib\site-packages\django\db\models\query.py", line 1805, in _insert
    return query.get_compiler(using=using).execute_sql(returning_fields)
           ~~~~~~~~~~~~~~~~~~~~~~~~~~~~~~~~~~~~~~~~~~~^^^^^^^^^^^^^^^^^^
  File "C:\Users\Technomowj\AppData\Local\Programs\Python\Python313\Lib\site-packages\django\db\models\sql\compiler.py", line 1822, in execute_sql
    cursor.execute(sql, params)
    ~~~~~~~~~~~~~~^^^^^^^^^^^^^
  File "C:\Users\Technomowj\AppData\Local\Programs\Python\Python313\Lib\site-packages\django\db\backends\utils.py", line 102, in execute
    return super().execute(sql, params)
           ~~~~~~~~~~~~~~~^^^^^^^^^^^^^
  File "C:\Users\Technomowj\AppData\Local\Programs\Python\Python313\Lib\site-packages\django\db\backends\utils.py", line 67, in execute
    return self._execute_with_wrappers(
           ~~~~~~~~~~~~~~~~~~~~~~~~~~~^
        sql, params, many=False, executor=self._execute
        ^^^^^^^^^^^^^^^^^^^^^^^^^^^^^^^^^^^^^^^^^^^^^^^
    )
    ^
  File "C:\Users\Technomowj\AppData\Local\Programs\Python\Python313\Lib\site-packages\django\db\backends\utils.py", line 80, in _execute_with_wrappers
    return executor(sql, params, many, context)
  File "C:\Users\Technomowj\AppData\Local\Programs\Python\Python313\Lib\site-packages\django\db\backends\utils.py", line 84, in _execute
    with self.db.wrap_database_errors:
         ^^^^^^^^^^^^^^^^^^^^^^^^^^^^
  File "C:\Users\Technomowj\AppData\Local\Programs\Python\Python313\Lib\site-packages\django\db\utils.py", line 91, in __exit__
    raise dj_exc_value.with_traceback(traceback) from exc_value
  File "C:\Users\Technomowj\AppData\Local\Programs\Python\Python313\Lib\site-packages\django\db\backends\utils.py", line 89, in _execute
    return self.cursor.execute(sql, params)
           ~~~~~~~~~~~~~~~~~~~^^^^^^^^^^^^^
  File "C:\Users\Technomowj\AppData\Local\Programs\Python\Python313\Lib\site-packages\django\db\backends\sqlite3\base.py", line 328, in execute
    return super().execute(query, params)
           ~~~~~~~~~~~~~~~^^^^^^^^^^^^^^^
django.db.utils.IntegrityError: UNIQUE constraint failed: game_gameroom.room_code
WARNING 2025-08-07 02:18:03,097 log 1200 26492 Not Found: /.well-known/appspecific/com.chrome.devtools.json
ERROR 2025-08-07 02:18:08,437 log 1200 26492 Internal Server Error: /api/rooms/create/
Traceback (most recent call last):
  File "C:\Users\Technomowj\AppData\Local\Programs\Python\Python313\Lib\site-packages\django\db\backends\utils.py", line 89, in _execute
    return self.cursor.execute(sql, params)
           ~~~~~~~~~~~~~~~~~~~^^^^^^^^^^^^^
  File "C:\Users\Technomowj\AppData\Local\Programs\Python\Python313\Lib\site-packages\django\db\backends\sqlite3\base.py", line 328, in execute
    return super().execute(query, params)
           ~~~~~~~~~~~~~~~^^^^^^^^^^^^^^^
sqlite3.IntegrityError: UNIQUE constraint failed: game_gameroom.room_code

The above exception was the direct cause of the following exception:

Traceback (most recent call last):
  File "C:\Users\Technomowj\AppData\Local\Programs\Python\Python313\Lib\site-packages\django\core\handlers\exception.py", line 55, in inner
    response = get_response(request)
  File "C:\Users\Technomowj\AppData\Local\Programs\Python\Python313\Lib\site-packages\django\core\handlers\base.py", line 197, in _get_response
    response = wrapped_callback(request, *callback_args, **callback_kwargs)
  File "C:\Users\Technomowj\AppData\Local\Programs\Python\Python313\Lib\site-packages\django\views\decorators\csrf.py", line 56, in wrapper_view
    return view_func(*args, **kwargs)
  File "C:\Users\Technomowj\AppData\Local\Programs\Python\Python313\Lib\site-packages\django\views\generic\base.py", line 104, in view
    return self.dispatch(request, *args, **kwargs)
           ~~~~~~~~~~~~~^^^^^^^^^^^^^^^^^^^^^^^^^^
  File "C:\Users\Technomowj\AppData\Local\Programs\Python\Python313\Lib\site-packages\rest_framework\views.py", line 509, in dispatch
    response = self.handle_exception(exc)
  File "C:\Users\Technomowj\AppData\Local\Programs\Python\Python313\Lib\site-packages\rest_framework\views.py", line 469, in handle_exception
    self.raise_uncaught_exception(exc)
    ~~~~~~~~~~~~~~~~~~~~~~~~~~~~~^^^^^
  File "C:\Users\Technomowj\AppData\Local\Programs\Python\Python313\Lib\site-packages\rest_framework\views.py", line 480, in raise_uncaught_exception
    raise exc
  File "C:\Users\Technomowj\AppData\Local\Programs\Python\Python313\Lib\site-packages\rest_framework\views.py", line 506, in dispatch
    response = handler(request, *args, **kwargs)
  File "C:\Users\Technomowj\AppData\Local\Programs\Python\Python313\Lib\site-packages\rest_framework\decorators.py", line 50, in handler
    return func(*args, **kwargs)
  File "D:\code\10\game\views.py", line 165, in create_room
    room = serializer.save(host=request.user)
  File "C:\Users\Technomowj\AppData\Local\Programs\Python\Python313\Lib\site-packages\rest_framework\serializers.py", line 212, in save
    self.instance = self.create(validated_data)
                    ~~~~~~~~~~~^^^^^^^^^^^^^^^^
  File "C:\Users\Technomowj\AppData\Local\Programs\Python\Python313\Lib\site-packages\rest_framework\serializers.py", line 962, in create
    instance = ModelClass._default_manager.create(**validated_data)
  File "C:\Users\Technomowj\AppData\Local\Programs\Python\Python313\Lib\site-packages\django\db\models\manager.py", line 87, in manager_method
    return getattr(self.get_queryset(), name)(*args, **kwargs)
           ~~~~~~~~~~~~~~~~~~~~~~~~~~~~~~~~~~^^^^^^^^^^^^^^^^^
  File "C:\Users\Technomowj\AppData\Local\Programs\Python\Python313\Lib\site-packages\django\db\models\query.py", line 658, in create
    obj.save(force_insert=True, using=self.db)
    ~~~~~~~~^^^^^^^^^^^^^^^^^^^^^^^^^^^^^^^^^^
  File "D:\code\10\game\models.py", line 116, in save
    super().save(*args, **kwargs)
    ~~~~~~~~~~~~^^^^^^^^^^^^^^^^^
  File "C:\Users\Technomowj\AppData\Local\Programs\Python\Python313\Lib\site-packages\django\db\models\base.py", line 814, in save
    self.save_base(
    ~~~~~~~~~~~~~~^
        using=using,
        ^^^^^^^^^^^^
    ...<2 lines>...
        update_fields=update_fields,
        ^^^^^^^^^^^^^^^^^^^^^^^^^^^^
    )
    ^
  File "C:\Users\Technomowj\AppData\Local\Programs\Python\Python313\Lib\site-packages\django\db\models\base.py", line 877, in save_base
    updated = self._save_table(
        raw,
    ...<4 lines>...
        update_fields,
    )
  File "C:\Users\Technomowj\AppData\Local\Programs\Python\Python313\Lib\site-packages\django\db\models\base.py", line 1020, in _save_table
    results = self._do_insert(
        cls._base_manager, using, fields, returning_fields, raw
    )
  File "C:\Users\Technomowj\AppData\Local\Programs\Python\Python313\Lib\site-packages\django\db\models\base.py", line 1061, in _do_insert
    return manager._insert(
           ~~~~~~~~~~~~~~~^
        [self],
        ^^^^^^^
    ...<3 lines>...
        raw=raw,
        ^^^^^^^^
    )
    ^
  File "C:\Users\Technomowj\AppData\Local\Programs\Python\Python313\Lib\site-packages\django\db\models\manager.py", line 87, in manager_method
    return getattr(self.get_queryset(), name)(*args, **kwargs)
           ~~~~~~~~~~~~~~~~~~~~~~~~~~~~~~~~~~^^^^^^^^^^^^^^^^^
  File "C:\Users\Technomowj\AppData\Local\Programs\Python\Python313\Lib\site-packages\django\db\models\query.py", line 1805, in _insert
    return query.get_compiler(using=using).execute_sql(returning_fields)
           ~~~~~~~~~~~~~~~~~~~~~~~~~~~~~~~~~~~~~~~~~~~^^^^^^^^^^^^^^^^^^
  File "C:\Users\Technomowj\AppData\Local\Programs\Python\Python313\Lib\site-packages\django\db\models\sql\compiler.py", line 1822, in execute_sql
    cursor.execute(sql, params)
    ~~~~~~~~~~~~~~^^^^^^^^^^^^^
  File "C:\Users\Technomowj\AppData\Local\Programs\Python\Python313\Lib\site-packages\django\db\backends\utils.py", line 102, in execute
    return super().execute(sql, params)
           ~~~~~~~~~~~~~~~^^^^^^^^^^^^^
  File "C:\Users\Technomowj\AppData\Local\Programs\Python\Python313\Lib\site-packages\django\db\backends\utils.py", line 67, in execute
    return self._execute_with_wrappers(
           ~~~~~~~~~~~~~~~~~~~~~~~~~~~^
        sql, params, many=False, executor=self._execute
        ^^^^^^^^^^^^^^^^^^^^^^^^^^^^^^^^^^^^^^^^^^^^^^^
    )
    ^
  File "C:\Users\Technomowj\AppData\Local\Programs\Python\Python313\Lib\site-packages\django\db\backends\utils.py", line 80, in _execute_with_wrappers
    return executor(sql, params, many, context)
  File "C:\Users\Technomowj\AppData\Local\Programs\Python\Python313\Lib\site-packages\django\db\backends\utils.py", line 84, in _execute
    with self.db.wrap_database_errors:
         ^^^^^^^^^^^^^^^^^^^^^^^^^^^^
  File "C:\Users\Technomowj\AppData\Local\Programs\Python\Python313\Lib\site-packages\django\db\utils.py", line 91, in __exit__
    raise dj_exc_value.with_traceback(traceback) from exc_value
  File "C:\Users\Technomowj\AppData\Local\Programs\Python\Python313\Lib\site-packages\django\db\backends\utils.py", line 89, in _execute
    return self.cursor.execute(sql, params)
           ~~~~~~~~~~~~~~~~~~~^^^^^^^^^^^^^
  File "C:\Users\Technomowj\AppData\Local\Programs\Python\Python313\Lib\site-packages\django\db\backends\sqlite3\base.py", line 328, in execute
    return super().execute(query, params)
           ~~~~~~~~~~~~~~~^^^^^^^^^^^^^^^
django.db.utils.IntegrityError: UNIQUE constraint failed: game_gameroom.room_code
WARNING 2025-08-07 02:18:46,158 log 1200 32708 Forbidden: /api/rooms/b1befc26-6ecd-4f9b-8859-0e2f3bcd5280/activity/
INFO 2025-08-07 02:20:01,817 autoreload 19148 11852 Watching for file changes with StatReloader
ERROR 2025-08-07 02:20:04,136 log 19148 30680 Internal Server Error: /api/rooms/create/
Traceback (most recent call last):
  File "C:\Users\Technomowj\AppData\Local\Programs\Python\Python313\Lib\site-packages\django\db\backends\utils.py", line 89, in _execute
    return self.cursor.execute(sql, params)
           ~~~~~~~~~~~~~~~~~~~^^^^^^^^^^^^^
  File "C:\Users\Technomowj\AppData\Local\Programs\Python\Python313\Lib\site-packages\django\db\backends\sqlite3\base.py", line 328, in execute
    return super().execute(query, params)
           ~~~~~~~~~~~~~~~^^^^^^^^^^^^^^^
sqlite3.IntegrityError: UNIQUE constraint failed: game_gameroom.room_code

The above exception was the direct cause of the following exception:

Traceback (most recent call last):
  File "C:\Users\Technomowj\AppData\Local\Programs\Python\Python313\Lib\site-packages\django\core\handlers\exception.py", line 55, in inner
    response = get_response(request)
  File "C:\Users\Technomowj\AppData\Local\Programs\Python\Python313\Lib\site-packages\django\core\handlers\base.py", line 197, in _get_response
    response = wrapped_callback(request, *callback_args, **callback_kwargs)
  File "C:\Users\Technomowj\AppData\Local\Programs\Python\Python313\Lib\site-packages\django\views\decorators\csrf.py", line 56, in wrapper_view
    return view_func(*args, **kwargs)
  File "C:\Users\Technomowj\AppData\Local\Programs\Python\Python313\Lib\site-packages\django\views\generic\base.py", line 104, in view
    return self.dispatch(request, *args, **kwargs)
           ~~~~~~~~~~~~~^^^^^^^^^^^^^^^^^^^^^^^^^^
  File "C:\Users\Technomowj\AppData\Local\Programs\Python\Python313\Lib\site-packages\rest_framework\views.py", line 509, in dispatch
    response = self.handle_exception(exc)
  File "C:\Users\Technomowj\AppData\Local\Programs\Python\Python313\Lib\site-packages\rest_framework\views.py", line 469, in handle_exception
    self.raise_uncaught_exception(exc)
    ~~~~~~~~~~~~~~~~~~~~~~~~~~~~~^^^^^
  File "C:\Users\Technomowj\AppData\Local\Programs\Python\Python313\Lib\site-packages\rest_framework\views.py", line 480, in raise_uncaught_exception
    raise exc
  File "C:\Users\Technomowj\AppData\Local\Programs\Python\Python313\Lib\site-packages\rest_framework\views.py", line 506, in dispatch
    response = handler(request, *args, **kwargs)
  File "C:\Users\Technomowj\AppData\Local\Programs\Python\Python313\Lib\site-packages\rest_framework\decorators.py", line 50, in handler
    return func(*args, **kwargs)
  File "D:\code\10\game\views.py", line 165, in create_room
    room = serializer.save(host=request.user)
  File "C:\Users\Technomowj\AppData\Local\Programs\Python\Python313\Lib\site-packages\rest_framework\serializers.py", line 212, in save
    self.instance = self.create(validated_data)
                    ~~~~~~~~~~~^^^^^^^^^^^^^^^^
  File "C:\Users\Technomowj\AppData\Local\Programs\Python\Python313\Lib\site-packages\rest_framework\serializers.py", line 962, in create
    instance = ModelClass._default_manager.create(**validated_data)
  File "C:\Users\Technomowj\AppData\Local\Programs\Python\Python313\Lib\site-packages\django\db\models\manager.py", line 87, in manager_method
    return getattr(self.get_queryset(), name)(*args, **kwargs)
           ~~~~~~~~~~~~~~~~~~~~~~~~~~~~~~~~~~^^^^^^^^^^^^^^^^^
  File "C:\Users\Technomowj\AppData\Local\Programs\Python\Python313\Lib\site-packages\django\db\models\query.py", line 658, in create
    obj.save(force_insert=True, using=self.db)
    ~~~~~~~~^^^^^^^^^^^^^^^^^^^^^^^^^^^^^^^^^^
  File "D:\code\10\game\models.py", line 116, in save
    super().save(*args, **kwargs)
    ~~~~~~~~~~~~^^^^^^^^^^^^^^^^^
  File "C:\Users\Technomowj\AppData\Local\Programs\Python\Python313\Lib\site-packages\django\db\models\base.py", line 814, in save
    self.save_base(
    ~~~~~~~~~~~~~~^
        using=using,
        ^^^^^^^^^^^^
    ...<2 lines>...
        update_fields=update_fields,
        ^^^^^^^^^^^^^^^^^^^^^^^^^^^^
    )
    ^
  File "C:\Users\Technomowj\AppData\Local\Programs\Python\Python313\Lib\site-packages\django\db\models\base.py", line 877, in save_base
    updated = self._save_table(
        raw,
    ...<4 lines>...
        update_fields,
    )
  File "C:\Users\Technomowj\AppData\Local\Programs\Python\Python313\Lib\site-packages\django\db\models\base.py", line 1020, in _save_table
    results = self._do_insert(
        cls._base_manager, using, fields, returning_fields, raw
    )
  File "C:\Users\Technomowj\AppData\Local\Programs\Python\Python313\Lib\site-packages\django\db\models\base.py", line 1061, in _do_insert
    return manager._insert(
           ~~~~~~~~~~~~~~~^
        [self],
        ^^^^^^^
    ...<3 lines>...
        raw=raw,
        ^^^^^^^^
    )
    ^
  File "C:\Users\Technomowj\AppData\Local\Programs\Python\Python313\Lib\site-packages\django\db\models\manager.py", line 87, in manager_method
    return getattr(self.get_queryset(), name)(*args, **kwargs)
           ~~~~~~~~~~~~~~~~~~~~~~~~~~~~~~~~~~^^^^^^^^^^^^^^^^^
  File "C:\Users\Technomowj\AppData\Local\Programs\Python\Python313\Lib\site-packages\django\db\models\query.py", line 1805, in _insert
    return query.get_compiler(using=using).execute_sql(returning_fields)
           ~~~~~~~~~~~~~~~~~~~~~~~~~~~~~~~~~~~~~~~~~~~^^^^^^^^^^^^^^^^^^
  File "C:\Users\Technomowj\AppData\Local\Programs\Python\Python313\Lib\site-packages\django\db\models\sql\compiler.py", line 1822, in execute_sql
    cursor.execute(sql, params)
    ~~~~~~~~~~~~~~^^^^^^^^^^^^^
  File "C:\Users\Technomowj\AppData\Local\Programs\Python\Python313\Lib\site-packages\django\db\backends\utils.py", line 102, in execute
    return super().execute(sql, params)
           ~~~~~~~~~~~~~~~^^^^^^^^^^^^^
  File "C:\Users\Technomowj\AppData\Local\Programs\Python\Python313\Lib\site-packages\django\db\backends\utils.py", line 67, in execute
    return self._execute_with_wrappers(
           ~~~~~~~~~~~~~~~~~~~~~~~~~~~^
        sql, params, many=False, executor=self._execute
        ^^^^^^^^^^^^^^^^^^^^^^^^^^^^^^^^^^^^^^^^^^^^^^^
    )
    ^
  File "C:\Users\Technomowj\AppData\Local\Programs\Python\Python313\Lib\site-packages\django\db\backends\utils.py", line 80, in _execute_with_wrappers
    return executor(sql, params, many, context)
  File "C:\Users\Technomowj\AppData\Local\Programs\Python\Python313\Lib\site-packages\django\db\backends\utils.py", line 84, in _execute
    with self.db.wrap_database_errors:
         ^^^^^^^^^^^^^^^^^^^^^^^^^^^^
  File "C:\Users\Technomowj\AppData\Local\Programs\Python\Python313\Lib\site-packages\django\db\utils.py", line 91, in __exit__
    raise dj_exc_value.with_traceback(traceback) from exc_value
  File "C:\Users\Technomowj\AppData\Local\Programs\Python\Python313\Lib\site-packages\django\db\backends\utils.py", line 89, in _execute
    return self.cursor.execute(sql, params)
           ~~~~~~~~~~~~~~~~~~~^^^^^^^^^^^^^
  File "C:\Users\Technomowj\AppData\Local\Programs\Python\Python313\Lib\site-packages\django\db\backends\sqlite3\base.py", line 328, in execute
    return super().execute(query, params)
           ~~~~~~~~~~~~~~~^^^^^^^^^^^^^^^
django.db.utils.IntegrityError: UNIQUE constraint failed: game_gameroom.room_code
ERROR 2025-08-07 02:20:37,048 log 19148 30680 Internal Server Error: /api/rooms/create/
Traceback (most recent call last):
  File "C:\Users\Technomowj\AppData\Local\Programs\Python\Python313\Lib\site-packages\django\db\backends\utils.py", line 89, in _execute
    return self.cursor.execute(sql, params)
           ~~~~~~~~~~~~~~~~~~~^^^^^^^^^^^^^
  File "C:\Users\Technomowj\AppData\Local\Programs\Python\Python313\Lib\site-packages\django\db\backends\sqlite3\base.py", line 328, in execute
    return super().execute(query, params)
           ~~~~~~~~~~~~~~~^^^^^^^^^^^^^^^
sqlite3.IntegrityError: UNIQUE constraint failed: game_gameroom.room_code

The above exception was the direct cause of the following exception:

Traceback (most recent call last):
  File "C:\Users\Technomowj\AppData\Local\Programs\Python\Python313\Lib\site-packages\django\core\handlers\exception.py", line 55, in inner
    response = get_response(request)
  File "C:\Users\Technomowj\AppData\Local\Programs\Python\Python313\Lib\site-packages\django\core\handlers\base.py", line 197, in _get_response
    response = wrapped_callback(request, *callback_args, **callback_kwargs)
  File "C:\Users\Technomowj\AppData\Local\Programs\Python\Python313\Lib\site-packages\django\views\decorators\csrf.py", line 56, in wrapper_view
    return view_func(*args, **kwargs)
  File "C:\Users\Technomowj\AppData\Local\Programs\Python\Python313\Lib\site-packages\django\views\generic\base.py", line 104, in view
    return self.dispatch(request, *args, **kwargs)
           ~~~~~~~~~~~~~^^^^^^^^^^^^^^^^^^^^^^^^^^
  File "C:\Users\Technomowj\AppData\Local\Programs\Python\Python313\Lib\site-packages\rest_framework\views.py", line 509, in dispatch
    response = self.handle_exception(exc)
  File "C:\Users\Technomowj\AppData\Local\Programs\Python\Python313\Lib\site-packages\rest_framework\views.py", line 469, in handle_exception
    self.raise_uncaught_exception(exc)
    ~~~~~~~~~~~~~~~~~~~~~~~~~~~~~^^^^^
  File "C:\Users\Technomowj\AppData\Local\Programs\Python\Python313\Lib\site-packages\rest_framework\views.py", line 480, in raise_uncaught_exception
    raise exc
  File "C:\Users\Technomowj\AppData\Local\Programs\Python\Python313\Lib\site-packages\rest_framework\views.py", line 506, in dispatch
    response = handler(request, *args, **kwargs)
  File "C:\Users\Technomowj\AppData\Local\Programs\Python\Python313\Lib\site-packages\rest_framework\decorators.py", line 50, in handler
    return func(*args, **kwargs)
  File "D:\code\10\game\views.py", line 165, in create_room
    room = serializer.save(host=request.user)
  File "C:\Users\Technomowj\AppData\Local\Programs\Python\Python313\Lib\site-packages\rest_framework\serializers.py", line 212, in save
    self.instance = self.create(validated_data)
                    ~~~~~~~~~~~^^^^^^^^^^^^^^^^
  File "C:\Users\Technomowj\AppData\Local\Programs\Python\Python313\Lib\site-packages\rest_framework\serializers.py", line 962, in create
    instance = ModelClass._default_manager.create(**validated_data)
  File "C:\Users\Technomowj\AppData\Local\Programs\Python\Python313\Lib\site-packages\django\db\models\manager.py", line 87, in manager_method
    return getattr(self.get_queryset(), name)(*args, **kwargs)
           ~~~~~~~~~~~~~~~~~~~~~~~~~~~~~~~~~~^^^^^^^^^^^^^^^^^
  File "C:\Users\Technomowj\AppData\Local\Programs\Python\Python313\Lib\site-packages\django\db\models\query.py", line 658, in create
    obj.save(force_insert=True, using=self.db)
    ~~~~~~~~^^^^^^^^^^^^^^^^^^^^^^^^^^^^^^^^^^
  File "D:\code\10\game\models.py", line 116, in save
    super().save(*args, **kwargs)
    ~~~~~~~~~~~~^^^^^^^^^^^^^^^^^
  File "C:\Users\Technomowj\AppData\Local\Programs\Python\Python313\Lib\site-packages\django\db\models\base.py", line 814, in save
    self.save_base(
    ~~~~~~~~~~~~~~^
        using=using,
        ^^^^^^^^^^^^
    ...<2 lines>...
        update_fields=update_fields,
        ^^^^^^^^^^^^^^^^^^^^^^^^^^^^
    )
    ^
  File "C:\Users\Technomowj\AppData\Local\Programs\Python\Python313\Lib\site-packages\django\db\models\base.py", line 877, in save_base
    updated = self._save_table(
        raw,
    ...<4 lines>...
        update_fields,
    )
  File "C:\Users\Technomowj\AppData\Local\Programs\Python\Python313\Lib\site-packages\django\db\models\base.py", line 1020, in _save_table
    results = self._do_insert(
        cls._base_manager, using, fields, returning_fields, raw
    )
  File "C:\Users\Technomowj\AppData\Local\Programs\Python\Python313\Lib\site-packages\django\db\models\base.py", line 1061, in _do_insert
    return manager._insert(
           ~~~~~~~~~~~~~~~^
        [self],
        ^^^^^^^
    ...<3 lines>...
        raw=raw,
        ^^^^^^^^
    )
    ^
  File "C:\Users\Technomowj\AppData\Local\Programs\Python\Python313\Lib\site-packages\django\db\models\manager.py", line 87, in manager_method
    return getattr(self.get_queryset(), name)(*args, **kwargs)
           ~~~~~~~~~~~~~~~~~~~~~~~~~~~~~~~~~~^^^^^^^^^^^^^^^^^
  File "C:\Users\Technomowj\AppData\Local\Programs\Python\Python313\Lib\site-packages\django\db\models\query.py", line 1805, in _insert
    return query.get_compiler(using=using).execute_sql(returning_fields)
           ~~~~~~~~~~~~~~~~~~~~~~~~~~~~~~~~~~~~~~~~~~~^^^^^^^^^^^^^^^^^^
  File "C:\Users\Technomowj\AppData\Local\Programs\Python\Python313\Lib\site-packages\django\db\models\sql\compiler.py", line 1822, in execute_sql
    cursor.execute(sql, params)
    ~~~~~~~~~~~~~~^^^^^^^^^^^^^
  File "C:\Users\Technomowj\AppData\Local\Programs\Python\Python313\Lib\site-packages\django\db\backends\utils.py", line 102, in execute
    return super().execute(sql, params)
           ~~~~~~~~~~~~~~~^^^^^^^^^^^^^
  File "C:\Users\Technomowj\AppData\Local\Programs\Python\Python313\Lib\site-packages\django\db\backends\utils.py", line 67, in execute
    return self._execute_with_wrappers(
           ~~~~~~~~~~~~~~~~~~~~~~~~~~~^
        sql, params, many=False, executor=self._execute
        ^^^^^^^^^^^^^^^^^^^^^^^^^^^^^^^^^^^^^^^^^^^^^^^
    )
    ^
  File "C:\Users\Technomowj\AppData\Local\Programs\Python\Python313\Lib\site-packages\django\db\backends\utils.py", line 80, in _execute_with_wrappers
    return executor(sql, params, many, context)
  File "C:\Users\Technomowj\AppData\Local\Programs\Python\Python313\Lib\site-packages\django\db\backends\utils.py", line 84, in _execute
    with self.db.wrap_database_errors:
         ^^^^^^^^^^^^^^^^^^^^^^^^^^^^
  File "C:\Users\Technomowj\AppData\Local\Programs\Python\Python313\Lib\site-packages\django\db\utils.py", line 91, in __exit__
    raise dj_exc_value.with_traceback(traceback) from exc_value
  File "C:\Users\Technomowj\AppData\Local\Programs\Python\Python313\Lib\site-packages\django\db\backends\utils.py", line 89, in _execute
    return self.cursor.execute(sql, params)
           ~~~~~~~~~~~~~~~~~~~^^^^^^^^^^^^^
  File "C:\Users\Technomowj\AppData\Local\Programs\Python\Python313\Lib\site-packages\django\db\backends\sqlite3\base.py", line 328, in execute
    return super().execute(query, params)
           ~~~~~~~~~~~~~~~^^^^^^^^^^^^^^^
django.db.utils.IntegrityError: UNIQUE constraint failed: game_gameroom.room_code
INFO 2025-08-07 02:20:43,541 autoreload 27136 31828 Watching for file changes with StatReloader
ERROR 2025-08-07 02:20:45,302 log 27136 21380 Internal Server Error: /api/rooms/create/
Traceback (most recent call last):
  File "C:\Users\Technomowj\AppData\Local\Programs\Python\Python313\Lib\site-packages\django\db\backends\utils.py", line 89, in _execute
    return self.cursor.execute(sql, params)
           ~~~~~~~~~~~~~~~~~~~^^^^^^^^^^^^^
  File "C:\Users\Technomowj\AppData\Local\Programs\Python\Python313\Lib\site-packages\django\db\backends\sqlite3\base.py", line 328, in execute
    return super().execute(query, params)
           ~~~~~~~~~~~~~~~^^^^^^^^^^^^^^^
sqlite3.IntegrityError: UNIQUE constraint failed: game_gameroom.room_code

The above exception was the direct cause of the following exception:

Traceback (most recent call last):
  File "C:\Users\Technomowj\AppData\Local\Programs\Python\Python313\Lib\site-packages\django\core\handlers\exception.py", line 55, in inner
    response = get_response(request)
  File "C:\Users\Technomowj\AppData\Local\Programs\Python\Python313\Lib\site-packages\django\core\handlers\base.py", line 197, in _get_response
    response = wrapped_callback(request, *callback_args, **callback_kwargs)
  File "C:\Users\Technomowj\AppData\Local\Programs\Python\Python313\Lib\site-packages\django\views\decorators\csrf.py", line 56, in wrapper_view
    return view_func(*args, **kwargs)
  File "C:\Users\Technomowj\AppData\Local\Programs\Python\Python313\Lib\site-packages\django\views\generic\base.py", line 104, in view
    return self.dispatch(request, *args, **kwargs)
           ~~~~~~~~~~~~~^^^^^^^^^^^^^^^^^^^^^^^^^^
  File "C:\Users\Technomowj\AppData\Local\Programs\Python\Python313\Lib\site-packages\rest_framework\views.py", line 509, in dispatch
    response = self.handle_exception(exc)
  File "C:\Users\Technomowj\AppData\Local\Programs\Python\Python313\Lib\site-packages\rest_framework\views.py", line 469, in handle_exception
    self.raise_uncaught_exception(exc)
    ~~~~~~~~~~~~~~~~~~~~~~~~~~~~~^^^^^
  File "C:\Users\Technomowj\AppData\Local\Programs\Python\Python313\Lib\site-packages\rest_framework\views.py", line 480, in raise_uncaught_exception
    raise exc
  File "C:\Users\Technomowj\AppData\Local\Programs\Python\Python313\Lib\site-packages\rest_framework\views.py", line 506, in dispatch
    response = handler(request, *args, **kwargs)
  File "C:\Users\Technomowj\AppData\Local\Programs\Python\Python313\Lib\site-packages\rest_framework\decorators.py", line 50, in handler
    return func(*args, **kwargs)
  File "D:\code\10\game\views.py", line 165, in create_room
    room = serializer.save(host=request.user)
  File "C:\Users\Technomowj\AppData\Local\Programs\Python\Python313\Lib\site-packages\rest_framework\serializers.py", line 212, in save
    self.instance = self.create(validated_data)
                    ~~~~~~~~~~~^^^^^^^^^^^^^^^^
  File "C:\Users\Technomowj\AppData\Local\Programs\Python\Python313\Lib\site-packages\rest_framework\serializers.py", line 962, in create
    instance = ModelClass._default_manager.create(**validated_data)
  File "C:\Users\Technomowj\AppData\Local\Programs\Python\Python313\Lib\site-packages\django\db\models\manager.py", line 87, in manager_method
    return getattr(self.get_queryset(), name)(*args, **kwargs)
           ~~~~~~~~~~~~~~~~~~~~~~~~~~~~~~~~~~^^^^^^^^^^^^^^^^^
  File "C:\Users\Technomowj\AppData\Local\Programs\Python\Python313\Lib\site-packages\django\db\models\query.py", line 658, in create
    obj.save(force_insert=True, using=self.db)
    ~~~~~~~~^^^^^^^^^^^^^^^^^^^^^^^^^^^^^^^^^^
  File "D:\code\10\game\models.py", line 116, in save
    super().save(*args, **kwargs)
    ~~~~~~~~~~~~^^^^^^^^^^^^^^^^^
  File "C:\Users\Technomowj\AppData\Local\Programs\Python\Python313\Lib\site-packages\django\db\models\base.py", line 814, in save
    self.save_base(
    ~~~~~~~~~~~~~~^
        using=using,
        ^^^^^^^^^^^^
    ...<2 lines>...
        update_fields=update_fields,
        ^^^^^^^^^^^^^^^^^^^^^^^^^^^^
    )
    ^
  File "C:\Users\Technomowj\AppData\Local\Programs\Python\Python313\Lib\site-packages\django\db\models\base.py", line 877, in save_base
    updated = self._save_table(
        raw,
    ...<4 lines>...
        update_fields,
    )
  File "C:\Users\Technomowj\AppData\Local\Programs\Python\Python313\Lib\site-packages\django\db\models\base.py", line 1020, in _save_table
    results = self._do_insert(
        cls._base_manager, using, fields, returning_fields, raw
    )
  File "C:\Users\Technomowj\AppData\Local\Programs\Python\Python313\Lib\site-packages\django\db\models\base.py", line 1061, in _do_insert
    return manager._insert(
           ~~~~~~~~~~~~~~~^
        [self],
        ^^^^^^^
    ...<3 lines>...
        raw=raw,
        ^^^^^^^^
    )
    ^
  File "C:\Users\Technomowj\AppData\Local\Programs\Python\Python313\Lib\site-packages\django\db\models\manager.py", line 87, in manager_method
    return getattr(self.get_queryset(), name)(*args, **kwargs)
           ~~~~~~~~~~~~~~~~~~~~~~~~~~~~~~~~~~^^^^^^^^^^^^^^^^^
  File "C:\Users\Technomowj\AppData\Local\Programs\Python\Python313\Lib\site-packages\django\db\models\query.py", line 1805, in _insert
    return query.get_compiler(using=using).execute_sql(returning_fields)
           ~~~~~~~~~~~~~~~~~~~~~~~~~~~~~~~~~~~~~~~~~~~^^^^^^^^^^^^^^^^^^
  File "C:\Users\Technomowj\AppData\Local\Programs\Python\Python313\Lib\site-packages\django\db\models\sql\compiler.py", line 1822, in execute_sql
    cursor.execute(sql, params)
    ~~~~~~~~~~~~~~^^^^^^^^^^^^^
  File "C:\Users\Technomowj\AppData\Local\Programs\Python\Python313\Lib\site-packages\django\db\backends\utils.py", line 102, in execute
    return super().execute(sql, params)
           ~~~~~~~~~~~~~~~^^^^^^^^^^^^^
  File "C:\Users\Technomowj\AppData\Local\Programs\Python\Python313\Lib\site-packages\django\db\backends\utils.py", line 67, in execute
    return self._execute_with_wrappers(
           ~~~~~~~~~~~~~~~~~~~~~~~~~~~^
        sql, params, many=False, executor=self._execute
        ^^^^^^^^^^^^^^^^^^^^^^^^^^^^^^^^^^^^^^^^^^^^^^^
    )
    ^
  File "C:\Users\Technomowj\AppData\Local\Programs\Python\Python313\Lib\site-packages\django\db\backends\utils.py", line 80, in _execute_with_wrappers
    return executor(sql, params, many, context)
  File "C:\Users\Technomowj\AppData\Local\Programs\Python\Python313\Lib\site-packages\django\db\backends\utils.py", line 84, in _execute
    with self.db.wrap_database_errors:
         ^^^^^^^^^^^^^^^^^^^^^^^^^^^^
  File "C:\Users\Technomowj\AppData\Local\Programs\Python\Python313\Lib\site-packages\django\db\utils.py", line 91, in __exit__
    raise dj_exc_value.with_traceback(traceback) from exc_value
  File "C:\Users\Technomowj\AppData\Local\Programs\Python\Python313\Lib\site-packages\django\db\backends\utils.py", line 89, in _execute
    return self.cursor.execute(sql, params)
           ~~~~~~~~~~~~~~~~~~~^^^^^^^^^^^^^
  File "C:\Users\Technomowj\AppData\Local\Programs\Python\Python313\Lib\site-packages\django\db\backends\sqlite3\base.py", line 328, in execute
    return super().execute(query, params)
           ~~~~~~~~~~~~~~~^^^^^^^^^^^^^^^
django.db.utils.IntegrityError: UNIQUE constraint failed: game_gameroom.room_code
WARNING 2025-08-07 02:20:46,161 log 27136 28544 Forbidden: /api/rooms/b1befc26-6ecd-4f9b-8859-0e2f3bcd5280/activity/
ERROR 2025-08-07 02:20:52,399 log 27136 21380 Internal Server Error: /api/rooms/create/
Traceback (most recent call last):
  File "C:\Users\Technomowj\AppData\Local\Programs\Python\Python313\Lib\site-packages\django\db\backends\utils.py", line 89, in _execute
    return self.cursor.execute(sql, params)
           ~~~~~~~~~~~~~~~~~~~^^^^^^^^^^^^^
  File "C:\Users\Technomowj\AppData\Local\Programs\Python\Python313\Lib\site-packages\django\db\backends\sqlite3\base.py", line 328, in execute
    return super().execute(query, params)
           ~~~~~~~~~~~~~~~^^^^^^^^^^^^^^^
sqlite3.IntegrityError: UNIQUE constraint failed: game_gameroom.room_code

The above exception was the direct cause of the following exception:

Traceback (most recent call last):
  File "C:\Users\Technomowj\AppData\Local\Programs\Python\Python313\Lib\site-packages\django\core\handlers\exception.py", line 55, in inner
    response = get_response(request)
  File "C:\Users\Technomowj\AppData\Local\Programs\Python\Python313\Lib\site-packages\django\core\handlers\base.py", line 197, in _get_response
    response = wrapped_callback(request, *callback_args, **callback_kwargs)
  File "C:\Users\Technomowj\AppData\Local\Programs\Python\Python313\Lib\site-packages\django\views\decorators\csrf.py", line 56, in wrapper_view
    return view_func(*args, **kwargs)
  File "C:\Users\Technomowj\AppData\Local\Programs\Python\Python313\Lib\site-packages\django\views\generic\base.py", line 104, in view
    return self.dispatch(request, *args, **kwargs)
           ~~~~~~~~~~~~~^^^^^^^^^^^^^^^^^^^^^^^^^^
  File "C:\Users\Technomowj\AppData\Local\Programs\Python\Python313\Lib\site-packages\rest_framework\views.py", line 509, in dispatch
    response = self.handle_exception(exc)
  File "C:\Users\Technomowj\AppData\Local\Programs\Python\Python313\Lib\site-packages\rest_framework\views.py", line 469, in handle_exception
    self.raise_uncaught_exception(exc)
    ~~~~~~~~~~~~~~~~~~~~~~~~~~~~~^^^^^
  File "C:\Users\Technomowj\AppData\Local\Programs\Python\Python313\Lib\site-packages\rest_framework\views.py", line 480, in raise_uncaught_exception
    raise exc
  File "C:\Users\Technomowj\AppData\Local\Programs\Python\Python313\Lib\site-packages\rest_framework\views.py", line 506, in dispatch
    response = handler(request, *args, **kwargs)
  File "C:\Users\Technomowj\AppData\Local\Programs\Python\Python313\Lib\site-packages\rest_framework\decorators.py", line 50, in handler
    return func(*args, **kwargs)
  File "D:\code\10\game\views.py", line 165, in create_room
    room = serializer.save(host=request.user)
  File "C:\Users\Technomowj\AppData\Local\Programs\Python\Python313\Lib\site-packages\rest_framework\serializers.py", line 212, in save
    self.instance = self.create(validated_data)
                    ~~~~~~~~~~~^^^^^^^^^^^^^^^^
  File "C:\Users\Technomowj\AppData\Local\Programs\Python\Python313\Lib\site-packages\rest_framework\serializers.py", line 962, in create
    instance = ModelClass._default_manager.create(**validated_data)
  File "C:\Users\Technomowj\AppData\Local\Programs\Python\Python313\Lib\site-packages\django\db\models\manager.py", line 87, in manager_method
    return getattr(self.get_queryset(), name)(*args, **kwargs)
           ~~~~~~~~~~~~~~~~~~~~~~~~~~~~~~~~~~^^^^^^^^^^^^^^^^^
  File "C:\Users\Technomowj\AppData\Local\Programs\Python\Python313\Lib\site-packages\django\db\models\query.py", line 658, in create
    obj.save(force_insert=True, using=self.db)
    ~~~~~~~~^^^^^^^^^^^^^^^^^^^^^^^^^^^^^^^^^^
  File "D:\code\10\game\models.py", line 116, in save
    super().save(*args, **kwargs)
    ~~~~~~~~~~~~^^^^^^^^^^^^^^^^^
  File "C:\Users\Technomowj\AppData\Local\Programs\Python\Python313\Lib\site-packages\django\db\models\base.py", line 814, in save
    self.save_base(
    ~~~~~~~~~~~~~~^
        using=using,
        ^^^^^^^^^^^^
    ...<2 lines>...
        update_fields=update_fields,
        ^^^^^^^^^^^^^^^^^^^^^^^^^^^^
    )
    ^
  File "C:\Users\Technomowj\AppData\Local\Programs\Python\Python313\Lib\site-packages\django\db\models\base.py", line 877, in save_base
    updated = self._save_table(
        raw,
    ...<4 lines>...
        update_fields,
    )
  File "C:\Users\Technomowj\AppData\Local\Programs\Python\Python313\Lib\site-packages\django\db\models\base.py", line 1020, in _save_table
    results = self._do_insert(
        cls._base_manager, using, fields, returning_fields, raw
    )
  File "C:\Users\Technomowj\AppData\Local\Programs\Python\Python313\Lib\site-packages\django\db\models\base.py", line 1061, in _do_insert
    return manager._insert(
           ~~~~~~~~~~~~~~~^
        [self],
        ^^^^^^^
    ...<3 lines>...
        raw=raw,
        ^^^^^^^^
    )
    ^
  File "C:\Users\Technomowj\AppData\Local\Programs\Python\Python313\Lib\site-packages\django\db\models\manager.py", line 87, in manager_method
    return getattr(self.get_queryset(), name)(*args, **kwargs)
           ~~~~~~~~~~~~~~~~~~~~~~~~~~~~~~~~~~^^^^^^^^^^^^^^^^^
  File "C:\Users\Technomowj\AppData\Local\Programs\Python\Python313\Lib\site-packages\django\db\models\query.py", line 1805, in _insert
    return query.get_compiler(using=using).execute_sql(returning_fields)
           ~~~~~~~~~~~~~~~~~~~~~~~~~~~~~~~~~~~~~~~~~~~^^^^^^^^^^^^^^^^^^
  File "C:\Users\Technomowj\AppData\Local\Programs\Python\Python313\Lib\site-packages\django\db\models\sql\compiler.py", line 1822, in execute_sql
    cursor.execute(sql, params)
    ~~~~~~~~~~~~~~^^^^^^^^^^^^^
  File "C:\Users\Technomowj\AppData\Local\Programs\Python\Python313\Lib\site-packages\django\db\backends\utils.py", line 102, in execute
    return super().execute(sql, params)
           ~~~~~~~~~~~~~~~^^^^^^^^^^^^^
  File "C:\Users\Technomowj\AppData\Local\Programs\Python\Python313\Lib\site-packages\django\db\backends\utils.py", line 67, in execute
    return self._execute_with_wrappers(
           ~~~~~~~~~~~~~~~~~~~~~~~~~~~^
        sql, params, many=False, executor=self._execute
        ^^^^^^^^^^^^^^^^^^^^^^^^^^^^^^^^^^^^^^^^^^^^^^^
    )
    ^
  File "C:\Users\Technomowj\AppData\Local\Programs\Python\Python313\Lib\site-packages\django\db\backends\utils.py", line 80, in _execute_with_wrappers
    return executor(sql, params, many, context)
  File "C:\Users\Technomowj\AppData\Local\Programs\Python\Python313\Lib\site-packages\django\db\backends\utils.py", line 84, in _execute
    with self.db.wrap_database_errors:
         ^^^^^^^^^^^^^^^^^^^^^^^^^^^^
  File "C:\Users\Technomowj\AppData\Local\Programs\Python\Python313\Lib\site-packages\django\db\utils.py", line 91, in __exit__
    raise dj_exc_value.with_traceback(traceback) from exc_value
  File "C:\Users\Technomowj\AppData\Local\Programs\Python\Python313\Lib\site-packages\django\db\backends\utils.py", line 89, in _execute
    return self.cursor.execute(sql, params)
           ~~~~~~~~~~~~~~~~~~~^^^^^^^^^^^^^
  File "C:\Users\Technomowj\AppData\Local\Programs\Python\Python313\Lib\site-packages\django\db\backends\sqlite3\base.py", line 328, in execute
    return super().execute(query, params)
           ~~~~~~~~~~~~~~~^^^^^^^^^^^^^^^
django.db.utils.IntegrityError: UNIQUE constraint failed: game_gameroom.room_code
WARNING 2025-08-07 02:21:46,153 log 27136 28544 Forbidden: /api/rooms/b1befc26-6ecd-4f9b-8859-0e2f3bcd5280/activity/
INFO 2025-08-07 02:24:41,641 autoreload 13640 26604 Watching for file changes with StatReloader
ERROR 2025-08-07 02:24:43,061 log 13640 24520 Internal Server Error: /api/rooms/create/
Traceback (most recent call last):
  File "C:\Users\Technomowj\AppData\Local\Programs\Python\Python313\Lib\site-packages\django\db\backends\utils.py", line 89, in _execute
    return self.cursor.execute(sql, params)
           ~~~~~~~~~~~~~~~~~~~^^^^^^^^^^^^^
  File "C:\Users\Technomowj\AppData\Local\Programs\Python\Python313\Lib\site-packages\django\db\backends\sqlite3\base.py", line 328, in execute
    return super().execute(query, params)
           ~~~~~~~~~~~~~~~^^^^^^^^^^^^^^^
sqlite3.IntegrityError: UNIQUE constraint failed: game_gameroom.room_code

The above exception was the direct cause of the following exception:

Traceback (most recent call last):
  File "C:\Users\Technomowj\AppData\Local\Programs\Python\Python313\Lib\site-packages\django\core\handlers\exception.py", line 55, in inner
    response = get_response(request)
  File "C:\Users\Technomowj\AppData\Local\Programs\Python\Python313\Lib\site-packages\django\core\handlers\base.py", line 197, in _get_response
    response = wrapped_callback(request, *callback_args, **callback_kwargs)
  File "C:\Users\Technomowj\AppData\Local\Programs\Python\Python313\Lib\site-packages\django\views\decorators\csrf.py", line 56, in wrapper_view
    return view_func(*args, **kwargs)
  File "C:\Users\Technomowj\AppData\Local\Programs\Python\Python313\Lib\site-packages\django\views\generic\base.py", line 104, in view
    return self.dispatch(request, *args, **kwargs)
           ~~~~~~~~~~~~~^^^^^^^^^^^^^^^^^^^^^^^^^^
  File "C:\Users\Technomowj\AppData\Local\Programs\Python\Python313\Lib\site-packages\rest_framework\views.py", line 509, in dispatch
    response = self.handle_exception(exc)
  File "C:\Users\Technomowj\AppData\Local\Programs\Python\Python313\Lib\site-packages\rest_framework\views.py", line 469, in handle_exception
    self.raise_uncaught_exception(exc)
    ~~~~~~~~~~~~~~~~~~~~~~~~~~~~~^^^^^
  File "C:\Users\Technomowj\AppData\Local\Programs\Python\Python313\Lib\site-packages\rest_framework\views.py", line 480, in raise_uncaught_exception
    raise exc
  File "C:\Users\Technomowj\AppData\Local\Programs\Python\Python313\Lib\site-packages\rest_framework\views.py", line 506, in dispatch
    response = handler(request, *args, **kwargs)
  File "C:\Users\Technomowj\AppData\Local\Programs\Python\Python313\Lib\site-packages\rest_framework\decorators.py", line 50, in handler
    return func(*args, **kwargs)
  File "D:\code\10\game\views.py", line 165, in create_room
    room = serializer.save(host=request.user)
  File "C:\Users\Technomowj\AppData\Local\Programs\Python\Python313\Lib\site-packages\rest_framework\serializers.py", line 212, in save
    self.instance = self.create(validated_data)
                    ~~~~~~~~~~~^^^^^^^^^^^^^^^^
  File "C:\Users\Technomowj\AppData\Local\Programs\Python\Python313\Lib\site-packages\rest_framework\serializers.py", line 962, in create
    instance = ModelClass._default_manager.create(**validated_data)
  File "C:\Users\Technomowj\AppData\Local\Programs\Python\Python313\Lib\site-packages\django\db\models\manager.py", line 87, in manager_method
    return getattr(self.get_queryset(), name)(*args, **kwargs)
           ~~~~~~~~~~~~~~~~~~~~~~~~~~~~~~~~~~^^^^^^^^^^^^^^^^^
  File "C:\Users\Technomowj\AppData\Local\Programs\Python\Python313\Lib\site-packages\django\db\models\query.py", line 658, in create
    obj.save(force_insert=True, using=self.db)
    ~~~~~~~~^^^^^^^^^^^^^^^^^^^^^^^^^^^^^^^^^^
  File "D:\code\10\game\models.py", line 116, in save
    super().save(*args, **kwargs)
    ~~~~~~~~~~~~^^^^^^^^^^^^^^^^^
  File "C:\Users\Technomowj\AppData\Local\Programs\Python\Python313\Lib\site-packages\django\db\models\base.py", line 814, in save
    self.save_base(
    ~~~~~~~~~~~~~~^
        using=using,
        ^^^^^^^^^^^^
    ...<2 lines>...
        update_fields=update_fields,
        ^^^^^^^^^^^^^^^^^^^^^^^^^^^^
    )
    ^
  File "C:\Users\Technomowj\AppData\Local\Programs\Python\Python313\Lib\site-packages\django\db\models\base.py", line 877, in save_base
    updated = self._save_table(
        raw,
    ...<4 lines>...
        update_fields,
    )
  File "C:\Users\Technomowj\AppData\Local\Programs\Python\Python313\Lib\site-packages\django\db\models\base.py", line 1020, in _save_table
    results = self._do_insert(
        cls._base_manager, using, fields, returning_fields, raw
    )
  File "C:\Users\Technomowj\AppData\Local\Programs\Python\Python313\Lib\site-packages\django\db\models\base.py", line 1061, in _do_insert
    return manager._insert(
           ~~~~~~~~~~~~~~~^
        [self],
        ^^^^^^^
    ...<3 lines>...
        raw=raw,
        ^^^^^^^^
    )
    ^
  File "C:\Users\Technomowj\AppData\Local\Programs\Python\Python313\Lib\site-packages\django\db\models\manager.py", line 87, in manager_method
    return getattr(self.get_queryset(), name)(*args, **kwargs)
           ~~~~~~~~~~~~~~~~~~~~~~~~~~~~~~~~~~^^^^^^^^^^^^^^^^^
  File "C:\Users\Technomowj\AppData\Local\Programs\Python\Python313\Lib\site-packages\django\db\models\query.py", line 1805, in _insert
    return query.get_compiler(using=using).execute_sql(returning_fields)
           ~~~~~~~~~~~~~~~~~~~~~~~~~~~~~~~~~~~~~~~~~~~^^^^^^^^^^^^^^^^^^
  File "C:\Users\Technomowj\AppData\Local\Programs\Python\Python313\Lib\site-packages\django\db\models\sql\compiler.py", line 1822, in execute_sql
    cursor.execute(sql, params)
    ~~~~~~~~~~~~~~^^^^^^^^^^^^^
  File "C:\Users\Technomowj\AppData\Local\Programs\Python\Python313\Lib\site-packages\django\db\backends\utils.py", line 102, in execute
    return super().execute(sql, params)
           ~~~~~~~~~~~~~~~^^^^^^^^^^^^^
  File "C:\Users\Technomowj\AppData\Local\Programs\Python\Python313\Lib\site-packages\django\db\backends\utils.py", line 67, in execute
    return self._execute_with_wrappers(
           ~~~~~~~~~~~~~~~~~~~~~~~~~~~^
        sql, params, many=False, executor=self._execute
        ^^^^^^^^^^^^^^^^^^^^^^^^^^^^^^^^^^^^^^^^^^^^^^^
    )
    ^
  File "C:\Users\Technomowj\AppData\Local\Programs\Python\Python313\Lib\site-packages\django\db\backends\utils.py", line 80, in _execute_with_wrappers
    return executor(sql, params, many, context)
  File "C:\Users\Technomowj\AppData\Local\Programs\Python\Python313\Lib\site-packages\django\db\backends\utils.py", line 84, in _execute
    with self.db.wrap_database_errors:
         ^^^^^^^^^^^^^^^^^^^^^^^^^^^^
  File "C:\Users\Technomowj\AppData\Local\Programs\Python\Python313\Lib\site-packages\django\db\utils.py", line 91, in __exit__
    raise dj_exc_value.with_traceback(traceback) from exc_value
  File "C:\Users\Technomowj\AppData\Local\Programs\Python\Python313\Lib\site-packages\django\db\backends\utils.py", line 89, in _execute
    return self.cursor.execute(sql, params)
           ~~~~~~~~~~~~~~~~~~~^^^^^^^^^^^^^
  File "C:\Users\Technomowj\AppData\Local\Programs\Python\Python313\Lib\site-packages\django\db\backends\sqlite3\base.py", line 328, in execute
    return super().execute(query, params)
           ~~~~~~~~~~~~~~~^^^^^^^^^^^^^^^
django.db.utils.IntegrityError: UNIQUE constraint failed: game_gameroom.room_code
ERROR 2025-08-07 02:24:51,109 log 13640 9632 Internal Server Error: /api/rooms/create/
Traceback (most recent call last):
  File "C:\Users\Technomowj\AppData\Local\Programs\Python\Python313\Lib\site-packages\django\db\backends\utils.py", line 89, in _execute
    return self.cursor.execute(sql, params)
           ~~~~~~~~~~~~~~~~~~~^^^^^^^^^^^^^
  File "C:\Users\Technomowj\AppData\Local\Programs\Python\Python313\Lib\site-packages\django\db\backends\sqlite3\base.py", line 328, in execute
    return super().execute(query, params)
           ~~~~~~~~~~~~~~~^^^^^^^^^^^^^^^
sqlite3.IntegrityError: UNIQUE constraint failed: game_gameroom.room_code

The above exception was the direct cause of the following exception:

Traceback (most recent call last):
  File "C:\Users\Technomowj\AppData\Local\Programs\Python\Python313\Lib\site-packages\django\core\handlers\exception.py", line 55, in inner
    response = get_response(request)
  File "C:\Users\Technomowj\AppData\Local\Programs\Python\Python313\Lib\site-packages\django\core\handlers\base.py", line 197, in _get_response
    response = wrapped_callback(request, *callback_args, **callback_kwargs)
  File "C:\Users\Technomowj\AppData\Local\Programs\Python\Python313\Lib\site-packages\django\views\decorators\csrf.py", line 56, in wrapper_view
    return view_func(*args, **kwargs)
  File "C:\Users\Technomowj\AppData\Local\Programs\Python\Python313\Lib\site-packages\django\views\generic\base.py", line 104, in view
    return self.dispatch(request, *args, **kwargs)
           ~~~~~~~~~~~~~^^^^^^^^^^^^^^^^^^^^^^^^^^
  File "C:\Users\Technomowj\AppData\Local\Programs\Python\Python313\Lib\site-packages\rest_framework\views.py", line 509, in dispatch
    response = self.handle_exception(exc)
  File "C:\Users\Technomowj\AppData\Local\Programs\Python\Python313\Lib\site-packages\rest_framework\views.py", line 469, in handle_exception
    self.raise_uncaught_exception(exc)
    ~~~~~~~~~~~~~~~~~~~~~~~~~~~~~^^^^^
  File "C:\Users\Technomowj\AppData\Local\Programs\Python\Python313\Lib\site-packages\rest_framework\views.py", line 480, in raise_uncaught_exception
    raise exc
  File "C:\Users\Technomowj\AppData\Local\Programs\Python\Python313\Lib\site-packages\rest_framework\views.py", line 506, in dispatch
    response = handler(request, *args, **kwargs)
  File "C:\Users\Technomowj\AppData\Local\Programs\Python\Python313\Lib\site-packages\rest_framework\decorators.py", line 50, in handler
    return func(*args, **kwargs)
  File "D:\code\10\game\views.py", line 165, in create_room
    room = serializer.save(host=request.user)
  File "C:\Users\Technomowj\AppData\Local\Programs\Python\Python313\Lib\site-packages\rest_framework\serializers.py", line 212, in save
    self.instance = self.create(validated_data)
                    ~~~~~~~~~~~^^^^^^^^^^^^^^^^
  File "C:\Users\Technomowj\AppData\Local\Programs\Python\Python313\Lib\site-packages\rest_framework\serializers.py", line 962, in create
    instance = ModelClass._default_manager.create(**validated_data)
  File "C:\Users\Technomowj\AppData\Local\Programs\Python\Python313\Lib\site-packages\django\db\models\manager.py", line 87, in manager_method
    return getattr(self.get_queryset(), name)(*args, **kwargs)
           ~~~~~~~~~~~~~~~~~~~~~~~~~~~~~~~~~~^^^^^^^^^^^^^^^^^
  File "C:\Users\Technomowj\AppData\Local\Programs\Python\Python313\Lib\site-packages\django\db\models\query.py", line 658, in create
    obj.save(force_insert=True, using=self.db)
    ~~~~~~~~^^^^^^^^^^^^^^^^^^^^^^^^^^^^^^^^^^
  File "D:\code\10\game\models.py", line 116, in save
    super().save(*args, **kwargs)
    ~~~~~~~~~~~~^^^^^^^^^^^^^^^^^
  File "C:\Users\Technomowj\AppData\Local\Programs\Python\Python313\Lib\site-packages\django\db\models\base.py", line 814, in save
    self.save_base(
    ~~~~~~~~~~~~~~^
        using=using,
        ^^^^^^^^^^^^
    ...<2 lines>...
        update_fields=update_fields,
        ^^^^^^^^^^^^^^^^^^^^^^^^^^^^
    )
    ^
  File "C:\Users\Technomowj\AppData\Local\Programs\Python\Python313\Lib\site-packages\django\db\models\base.py", line 877, in save_base
    updated = self._save_table(
        raw,
    ...<4 lines>...
        update_fields,
    )
  File "C:\Users\Technomowj\AppData\Local\Programs\Python\Python313\Lib\site-packages\django\db\models\base.py", line 1020, in _save_table
    results = self._do_insert(
        cls._base_manager, using, fields, returning_fields, raw
    )
  File "C:\Users\Technomowj\AppData\Local\Programs\Python\Python313\Lib\site-packages\django\db\models\base.py", line 1061, in _do_insert
    return manager._insert(
           ~~~~~~~~~~~~~~~^
        [self],
        ^^^^^^^
    ...<3 lines>...
        raw=raw,
        ^^^^^^^^
    )
    ^
  File "C:\Users\Technomowj\AppData\Local\Programs\Python\Python313\Lib\site-packages\django\db\models\manager.py", line 87, in manager_method
    return getattr(self.get_queryset(), name)(*args, **kwargs)
           ~~~~~~~~~~~~~~~~~~~~~~~~~~~~~~~~~~^^^^^^^^^^^^^^^^^
  File "C:\Users\Technomowj\AppData\Local\Programs\Python\Python313\Lib\site-packages\django\db\models\query.py", line 1805, in _insert
    return query.get_compiler(using=using).execute_sql(returning_fields)
           ~~~~~~~~~~~~~~~~~~~~~~~~~~~~~~~~~~~~~~~~~~~^^^^^^^^^^^^^^^^^^
  File "C:\Users\Technomowj\AppData\Local\Programs\Python\Python313\Lib\site-packages\django\db\models\sql\compiler.py", line 1822, in execute_sql
    cursor.execute(sql, params)
    ~~~~~~~~~~~~~~^^^^^^^^^^^^^
  File "C:\Users\Technomowj\AppData\Local\Programs\Python\Python313\Lib\site-packages\django\db\backends\utils.py", line 102, in execute
    return super().execute(sql, params)
           ~~~~~~~~~~~~~~~^^^^^^^^^^^^^
  File "C:\Users\Technomowj\AppData\Local\Programs\Python\Python313\Lib\site-packages\django\db\backends\utils.py", line 67, in execute
    return self._execute_with_wrappers(
           ~~~~~~~~~~~~~~~~~~~~~~~~~~~^
        sql, params, many=False, executor=self._execute
        ^^^^^^^^^^^^^^^^^^^^^^^^^^^^^^^^^^^^^^^^^^^^^^^
    )
    ^
  File "C:\Users\Technomowj\AppData\Local\Programs\Python\Python313\Lib\site-packages\django\db\backends\utils.py", line 80, in _execute_with_wrappers
    return executor(sql, params, many, context)
  File "C:\Users\Technomowj\AppData\Local\Programs\Python\Python313\Lib\site-packages\django\db\backends\utils.py", line 84, in _execute
    with self.db.wrap_database_errors:
         ^^^^^^^^^^^^^^^^^^^^^^^^^^^^
  File "C:\Users\Technomowj\AppData\Local\Programs\Python\Python313\Lib\site-packages\django\db\utils.py", line 91, in __exit__
    raise dj_exc_value.with_traceback(traceback) from exc_value
  File "C:\Users\Technomowj\AppData\Local\Programs\Python\Python313\Lib\site-packages\django\db\backends\utils.py", line 89, in _execute
    return self.cursor.execute(sql, params)
           ~~~~~~~~~~~~~~~~~~~^^^^^^^^^^^^^
  File "C:\Users\Technomowj\AppData\Local\Programs\Python\Python313\Lib\site-packages\django\db\backends\sqlite3\base.py", line 328, in execute
    return super().execute(query, params)
           ~~~~~~~~~~~~~~~^^^^^^^^^^^^^^^
django.db.utils.IntegrityError: UNIQUE constraint failed: game_gameroom.room_code
WARNING 2025-08-07 02:24:56,984 log 13640 27536 Not Found: /favicon.ico
WARNING 2025-08-07 02:25:03,446 log 13640 13116 Not Found: /favicon.ico
ERROR 2025-08-07 02:25:16,747 log 13640 9984 Internal Server Error: /api/rooms/create/
Traceback (most recent call last):
  File "C:\Users\Technomowj\AppData\Local\Programs\Python\Python313\Lib\site-packages\django\db\backends\utils.py", line 89, in _execute
    return self.cursor.execute(sql, params)
           ~~~~~~~~~~~~~~~~~~~^^^^^^^^^^^^^
  File "C:\Users\Technomowj\AppData\Local\Programs\Python\Python313\Lib\site-packages\django\db\backends\sqlite3\base.py", line 328, in execute
    return super().execute(query, params)
           ~~~~~~~~~~~~~~~^^^^^^^^^^^^^^^
sqlite3.IntegrityError: UNIQUE constraint failed: game_gameroom.room_code

The above exception was the direct cause of the following exception:

Traceback (most recent call last):
  File "C:\Users\Technomowj\AppData\Local\Programs\Python\Python313\Lib\site-packages\django\core\handlers\exception.py", line 55, in inner
    response = get_response(request)
  File "C:\Users\Technomowj\AppData\Local\Programs\Python\Python313\Lib\site-packages\django\core\handlers\base.py", line 197, in _get_response
    response = wrapped_callback(request, *callback_args, **callback_kwargs)
  File "C:\Users\Technomowj\AppData\Local\Programs\Python\Python313\Lib\site-packages\django\views\decorators\csrf.py", line 56, in wrapper_view
    return view_func(*args, **kwargs)
  File "C:\Users\Technomowj\AppData\Local\Programs\Python\Python313\Lib\site-packages\django\views\generic\base.py", line 104, in view
    return self.dispatch(request, *args, **kwargs)
           ~~~~~~~~~~~~~^^^^^^^^^^^^^^^^^^^^^^^^^^
  File "C:\Users\Technomowj\AppData\Local\Programs\Python\Python313\Lib\site-packages\rest_framework\views.py", line 509, in dispatch
    response = self.handle_exception(exc)
  File "C:\Users\Technomowj\AppData\Local\Programs\Python\Python313\Lib\site-packages\rest_framework\views.py", line 469, in handle_exception
    self.raise_uncaught_exception(exc)
    ~~~~~~~~~~~~~~~~~~~~~~~~~~~~~^^^^^
  File "C:\Users\Technomowj\AppData\Local\Programs\Python\Python313\Lib\site-packages\rest_framework\views.py", line 480, in raise_uncaught_exception
    raise exc
  File "C:\Users\Technomowj\AppData\Local\Programs\Python\Python313\Lib\site-packages\rest_framework\views.py", line 506, in dispatch
    response = handler(request, *args, **kwargs)
  File "C:\Users\Technomowj\AppData\Local\Programs\Python\Python313\Lib\site-packages\rest_framework\decorators.py", line 50, in handler
    return func(*args, **kwargs)
  File "D:\code\10\game\views.py", line 165, in create_room
    room = serializer.save(host=request.user)
  File "C:\Users\Technomowj\AppData\Local\Programs\Python\Python313\Lib\site-packages\rest_framework\serializers.py", line 212, in save
    self.instance = self.create(validated_data)
                    ~~~~~~~~~~~^^^^^^^^^^^^^^^^
  File "C:\Users\Technomowj\AppData\Local\Programs\Python\Python313\Lib\site-packages\rest_framework\serializers.py", line 962, in create
    instance = ModelClass._default_manager.create(**validated_data)
  File "C:\Users\Technomowj\AppData\Local\Programs\Python\Python313\Lib\site-packages\django\db\models\manager.py", line 87, in manager_method
    return getattr(self.get_queryset(), name)(*args, **kwargs)
           ~~~~~~~~~~~~~~~~~~~~~~~~~~~~~~~~~~^^^^^^^^^^^^^^^^^
  File "C:\Users\Technomowj\AppData\Local\Programs\Python\Python313\Lib\site-packages\django\db\models\query.py", line 658, in create
    obj.save(force_insert=True, using=self.db)
    ~~~~~~~~^^^^^^^^^^^^^^^^^^^^^^^^^^^^^^^^^^
  File "D:\code\10\game\models.py", line 116, in save
    super().save(*args, **kwargs)
    ~~~~~~~~~~~~^^^^^^^^^^^^^^^^^
  File "C:\Users\Technomowj\AppData\Local\Programs\Python\Python313\Lib\site-packages\django\db\models\base.py", line 814, in save
    self.save_base(
    ~~~~~~~~~~~~~~^
        using=using,
        ^^^^^^^^^^^^
    ...<2 lines>...
        update_fields=update_fields,
        ^^^^^^^^^^^^^^^^^^^^^^^^^^^^
    )
    ^
  File "C:\Users\Technomowj\AppData\Local\Programs\Python\Python313\Lib\site-packages\django\db\models\base.py", line 877, in save_base
    updated = self._save_table(
        raw,
    ...<4 lines>...
        update_fields,
    )
  File "C:\Users\Technomowj\AppData\Local\Programs\Python\Python313\Lib\site-packages\django\db\models\base.py", line 1020, in _save_table
    results = self._do_insert(
        cls._base_manager, using, fields, returning_fields, raw
    )
  File "C:\Users\Technomowj\AppData\Local\Programs\Python\Python313\Lib\site-packages\django\db\models\base.py", line 1061, in _do_insert
    return manager._insert(
           ~~~~~~~~~~~~~~~^
        [self],
        ^^^^^^^
    ...<3 lines>...
        raw=raw,
        ^^^^^^^^
    )
    ^
  File "C:\Users\Technomowj\AppData\Local\Programs\Python\Python313\Lib\site-packages\django\db\models\manager.py", line 87, in manager_method
    return getattr(self.get_queryset(), name)(*args, **kwargs)
           ~~~~~~~~~~~~~~~~~~~~~~~~~~~~~~~~~~^^^^^^^^^^^^^^^^^
  File "C:\Users\Technomowj\AppData\Local\Programs\Python\Python313\Lib\site-packages\django\db\models\query.py", line 1805, in _insert
    return query.get_compiler(using=using).execute_sql(returning_fields)
           ~~~~~~~~~~~~~~~~~~~~~~~~~~~~~~~~~~~~~~~~~~~^^^^^^^^^^^^^^^^^^
  File "C:\Users\Technomowj\AppData\Local\Programs\Python\Python313\Lib\site-packages\django\db\models\sql\compiler.py", line 1822, in execute_sql
    cursor.execute(sql, params)
    ~~~~~~~~~~~~~~^^^^^^^^^^^^^
  File "C:\Users\Technomowj\AppData\Local\Programs\Python\Python313\Lib\site-packages\django\db\backends\utils.py", line 102, in execute
    return super().execute(sql, params)
           ~~~~~~~~~~~~~~~^^^^^^^^^^^^^
  File "C:\Users\Technomowj\AppData\Local\Programs\Python\Python313\Lib\site-packages\django\db\backends\utils.py", line 67, in execute
    return self._execute_with_wrappers(
           ~~~~~~~~~~~~~~~~~~~~~~~~~~~^
        sql, params, many=False, executor=self._execute
        ^^^^^^^^^^^^^^^^^^^^^^^^^^^^^^^^^^^^^^^^^^^^^^^
    )
    ^
  File "C:\Users\Technomowj\AppData\Local\Programs\Python\Python313\Lib\site-packages\django\db\backends\utils.py", line 80, in _execute_with_wrappers
    return executor(sql, params, many, context)
  File "C:\Users\Technomowj\AppData\Local\Programs\Python\Python313\Lib\site-packages\django\db\backends\utils.py", line 84, in _execute
    with self.db.wrap_database_errors:
         ^^^^^^^^^^^^^^^^^^^^^^^^^^^^
  File "C:\Users\Technomowj\AppData\Local\Programs\Python\Python313\Lib\site-packages\django\db\utils.py", line 91, in __exit__
    raise dj_exc_value.with_traceback(traceback) from exc_value
  File "C:\Users\Technomowj\AppData\Local\Programs\Python\Python313\Lib\site-packages\django\db\backends\utils.py", line 89, in _execute
    return self.cursor.execute(sql, params)
           ~~~~~~~~~~~~~~~~~~~^^^^^^^^^^^^^
  File "C:\Users\Technomowj\AppData\Local\Programs\Python\Python313\Lib\site-packages\django\db\backends\sqlite3\base.py", line 328, in execute
    return super().execute(query, params)
           ~~~~~~~~~~~~~~~^^^^^^^^^^^^^^^
django.db.utils.IntegrityError: UNIQUE constraint failed: game_gameroom.room_code
ERROR 2025-08-07 02:25:27,865 log 13640 9984 Internal Server Error: /api/rooms/create/
Traceback (most recent call last):
  File "C:\Users\Technomowj\AppData\Local\Programs\Python\Python313\Lib\site-packages\django\db\backends\utils.py", line 89, in _execute
    return self.cursor.execute(sql, params)
           ~~~~~~~~~~~~~~~~~~~^^^^^^^^^^^^^
  File "C:\Users\Technomowj\AppData\Local\Programs\Python\Python313\Lib\site-packages\django\db\backends\sqlite3\base.py", line 328, in execute
    return super().execute(query, params)
           ~~~~~~~~~~~~~~~^^^^^^^^^^^^^^^
sqlite3.IntegrityError: UNIQUE constraint failed: game_gameroom.room_code

The above exception was the direct cause of the following exception:

Traceback (most recent call last):
  File "C:\Users\Technomowj\AppData\Local\Programs\Python\Python313\Lib\site-packages\django\core\handlers\exception.py", line 55, in inner
    response = get_response(request)
  File "C:\Users\Technomowj\AppData\Local\Programs\Python\Python313\Lib\site-packages\django\core\handlers\base.py", line 197, in _get_response
    response = wrapped_callback(request, *callback_args, **callback_kwargs)
  File "C:\Users\Technomowj\AppData\Local\Programs\Python\Python313\Lib\site-packages\django\views\decorators\csrf.py", line 56, in wrapper_view
    return view_func(*args, **kwargs)
  File "C:\Users\Technomowj\AppData\Local\Programs\Python\Python313\Lib\site-packages\django\views\generic\base.py", line 104, in view
    return self.dispatch(request, *args, **kwargs)
           ~~~~~~~~~~~~~^^^^^^^^^^^^^^^^^^^^^^^^^^
  File "C:\Users\Technomowj\AppData\Local\Programs\Python\Python313\Lib\site-packages\rest_framework\views.py", line 509, in dispatch
    response = self.handle_exception(exc)
  File "C:\Users\Technomowj\AppData\Local\Programs\Python\Python313\Lib\site-packages\rest_framework\views.py", line 469, in handle_exception
    self.raise_uncaught_exception(exc)
    ~~~~~~~~~~~~~~~~~~~~~~~~~~~~~^^^^^
  File "C:\Users\Technomowj\AppData\Local\Programs\Python\Python313\Lib\site-packages\rest_framework\views.py", line 480, in raise_uncaught_exception
    raise exc
  File "C:\Users\Technomowj\AppData\Local\Programs\Python\Python313\Lib\site-packages\rest_framework\views.py", line 506, in dispatch
    response = handler(request, *args, **kwargs)
  File "C:\Users\Technomowj\AppData\Local\Programs\Python\Python313\Lib\site-packages\rest_framework\decorators.py", line 50, in handler
    return func(*args, **kwargs)
  File "D:\code\10\game\views.py", line 165, in create_room
    room = serializer.save(host=request.user)
  File "C:\Users\Technomowj\AppData\Local\Programs\Python\Python313\Lib\site-packages\rest_framework\serializers.py", line 212, in save
    self.instance = self.create(validated_data)
                    ~~~~~~~~~~~^^^^^^^^^^^^^^^^
  File "C:\Users\Technomowj\AppData\Local\Programs\Python\Python313\Lib\site-packages\rest_framework\serializers.py", line 962, in create
    instance = ModelClass._default_manager.create(**validated_data)
  File "C:\Users\Technomowj\AppData\Local\Programs\Python\Python313\Lib\site-packages\django\db\models\manager.py", line 87, in manager_method
    return getattr(self.get_queryset(), name)(*args, **kwargs)
           ~~~~~~~~~~~~~~~~~~~~~~~~~~~~~~~~~~^^^^^^^^^^^^^^^^^
  File "C:\Users\Technomowj\AppData\Local\Programs\Python\Python313\Lib\site-packages\django\db\models\query.py", line 658, in create
    obj.save(force_insert=True, using=self.db)
    ~~~~~~~~^^^^^^^^^^^^^^^^^^^^^^^^^^^^^^^^^^
  File "D:\code\10\game\models.py", line 116, in save
    super().save(*args, **kwargs)
    ~~~~~~~~~~~~^^^^^^^^^^^^^^^^^
  File "C:\Users\Technomowj\AppData\Local\Programs\Python\Python313\Lib\site-packages\django\db\models\base.py", line 814, in save
    self.save_base(
    ~~~~~~~~~~~~~~^
        using=using,
        ^^^^^^^^^^^^
    ...<2 lines>...
        update_fields=update_fields,
        ^^^^^^^^^^^^^^^^^^^^^^^^^^^^
    )
    ^
  File "C:\Users\Technomowj\AppData\Local\Programs\Python\Python313\Lib\site-packages\django\db\models\base.py", line 877, in save_base
    updated = self._save_table(
        raw,
    ...<4 lines>...
        update_fields,
    )
  File "C:\Users\Technomowj\AppData\Local\Programs\Python\Python313\Lib\site-packages\django\db\models\base.py", line 1020, in _save_table
    results = self._do_insert(
        cls._base_manager, using, fields, returning_fields, raw
    )
  File "C:\Users\Technomowj\AppData\Local\Programs\Python\Python313\Lib\site-packages\django\db\models\base.py", line 1061, in _do_insert
    return manager._insert(
           ~~~~~~~~~~~~~~~^
        [self],
        ^^^^^^^
    ...<3 lines>...
        raw=raw,
        ^^^^^^^^
    )
    ^
  File "C:\Users\Technomowj\AppData\Local\Programs\Python\Python313\Lib\site-packages\django\db\models\manager.py", line 87, in manager_method
    return getattr(self.get_queryset(), name)(*args, **kwargs)
           ~~~~~~~~~~~~~~~~~~~~~~~~~~~~~~~~~~^^^^^^^^^^^^^^^^^
  File "C:\Users\Technomowj\AppData\Local\Programs\Python\Python313\Lib\site-packages\django\db\models\query.py", line 1805, in _insert
    return query.get_compiler(using=using).execute_sql(returning_fields)
           ~~~~~~~~~~~~~~~~~~~~~~~~~~~~~~~~~~~~~~~~~~~^^^^^^^^^^^^^^^^^^
  File "C:\Users\Technomowj\AppData\Local\Programs\Python\Python313\Lib\site-packages\django\db\models\sql\compiler.py", line 1822, in execute_sql
    cursor.execute(sql, params)
    ~~~~~~~~~~~~~~^^^^^^^^^^^^^
  File "C:\Users\Technomowj\AppData\Local\Programs\Python\Python313\Lib\site-packages\django\db\backends\utils.py", line 102, in execute
    return super().execute(sql, params)
           ~~~~~~~~~~~~~~~^^^^^^^^^^^^^
  File "C:\Users\Technomowj\AppData\Local\Programs\Python\Python313\Lib\site-packages\django\db\backends\utils.py", line 67, in execute
    return self._execute_with_wrappers(
           ~~~~~~~~~~~~~~~~~~~~~~~~~~~^
        sql, params, many=False, executor=self._execute
        ^^^^^^^^^^^^^^^^^^^^^^^^^^^^^^^^^^^^^^^^^^^^^^^
    )
    ^
  File "C:\Users\Technomowj\AppData\Local\Programs\Python\Python313\Lib\site-packages\django\db\backends\utils.py", line 80, in _execute_with_wrappers
    return executor(sql, params, many, context)
  File "C:\Users\Technomowj\AppData\Local\Programs\Python\Python313\Lib\site-packages\django\db\backends\utils.py", line 84, in _execute
    with self.db.wrap_database_errors:
         ^^^^^^^^^^^^^^^^^^^^^^^^^^^^
  File "C:\Users\Technomowj\AppData\Local\Programs\Python\Python313\Lib\site-packages\django\db\utils.py", line 91, in __exit__
    raise dj_exc_value.with_traceback(traceback) from exc_value
  File "C:\Users\Technomowj\AppData\Local\Programs\Python\Python313\Lib\site-packages\django\db\backends\utils.py", line 89, in _execute
    return self.cursor.execute(sql, params)
           ~~~~~~~~~~~~~~~~~~~^^^^^^^^^^^^^
  File "C:\Users\Technomowj\AppData\Local\Programs\Python\Python313\Lib\site-packages\django\db\backends\sqlite3\base.py", line 328, in execute
    return super().execute(query, params)
           ~~~~~~~~~~~~~~~^^^^^^^^^^^^^^^
django.db.utils.IntegrityError: UNIQUE constraint failed: game_gameroom.room_code
INFO 2025-08-07 02:26:05,731 autoreload 13640 26604 D:\code\10\game\models.py changed, reloading.
INFO 2025-08-07 02:26:06,318 autoreload 17796 31548 Watching for file changes with StatReloader
INFO 2025-08-07 02:26:57,710 autoreload 8044 13856 Watching for file changes with StatReloader
WARNING 2025-08-07 02:27:07,154 log 8044 11160 Forbidden: /api/auth/login/
WARNING 2025-08-07 02:27:22,525 log 8044 15056 Not Found: /favicon.ico
WARNING 2025-08-07 02:27:44,849 log 8044 3180 Unauthorized: /api/rooms/73a792c8-cfc7-4f7e-9ecb-a943b4c05776/activity/
WARNING 2025-08-07 02:27:46,162 log 8044 16596 Forbidden: /api/rooms/b1befc26-6ecd-4f9b-8859-0e2f3bcd5280/activity/
WARNING 2025-08-07 02:27:46,851 log 8044 3180 Forbidden: /api/rooms/73a792c8-cfc7-4f7e-9ecb-a943b4c05776/activity/
WARNING 2025-08-07 02:27:48,866 log 8044 3180 Forbidden: /api/rooms/73a792c8-cfc7-4f7e-9ecb-a943b4c05776/activity/
WARNING 2025-08-07 02:27:50,851 log 8044 3180 Forbidden: /api/rooms/73a792c8-cfc7-4f7e-9ecb-a943b4c05776/activity/
WARNING 2025-08-07 02:27:52,841 log 8044 3180 Forbidden: /api/rooms/73a792c8-cfc7-4f7e-9ecb-a943b4c05776/activity/
WARNING 2025-08-07 02:27:54,853 log 8044 3180 Forbidden: /api/rooms/73a792c8-cfc7-4f7e-9ecb-a943b4c05776/activity/
WARNING 2025-08-07 02:27:56,832 log 8044 3180 Forbidden: /api/rooms/73a792c8-cfc7-4f7e-9ecb-a943b4c05776/activity/
WARNING 2025-08-07 02:27:58,840 log 8044 3180 Forbidden: /api/rooms/73a792c8-cfc7-4f7e-9ecb-a943b4c05776/activity/
WARNING 2025-08-07 02:27:59,727 log 8044 3180 Forbidden: /api/auth/login/
WARNING 2025-08-07 02:28:00,853 log 8044 3180 Forbidden: /api/rooms/73a792c8-cfc7-4f7e-9ecb-a943b4c05776/activity/
WARNING 2025-08-07 02:28:02,847 log 8044 3180 Forbidden: /api/rooms/73a792c8-cfc7-4f7e-9ecb-a943b4c05776/activity/
WARNING 2025-08-07 02:28:04,946 log 8044 3180 Forbidden: /api/rooms/73a792c8-cfc7-4f7e-9ecb-a943b4c05776/activity/
WARNING 2025-08-07 02:28:05,861 log 8044 3180 Forbidden: /api/auth/login/
WARNING 2025-08-07 02:28:06,858 log 8044 3180 Forbidden: /api/rooms/73a792c8-cfc7-4f7e-9ecb-a943b4c05776/activity/
WARNING 2025-08-07 02:28:08,848 log 8044 3180 Forbidden: /api/rooms/73a792c8-cfc7-4f7e-9ecb-a943b4c05776/activity/
WARNING 2025-08-07 02:28:10,850 log 8044 3180 Forbidden: /api/rooms/73a792c8-cfc7-4f7e-9ecb-a943b4c05776/activity/
WARNING 2025-08-07 02:28:12,845 log 8044 3180 Forbidden: /api/rooms/73a792c8-cfc7-4f7e-9ecb-a943b4c05776/activity/
WARNING 2025-08-07 02:28:14,854 log 8044 3180 Forbidden: /api/rooms/73a792c8-cfc7-4f7e-9ecb-a943b4c05776/activity/
WARNING 2025-08-07 02:28:16,881 log 8044 3180 Forbidden: /api/rooms/73a792c8-cfc7-4f7e-9ecb-a943b4c05776/activity/
WARNING 2025-08-07 02:28:18,875 log 8044 3180 Forbidden: /api/rooms/73a792c8-cfc7-4f7e-9ecb-a943b4c05776/activity/
WARNING 2025-08-07 02:28:20,851 log 8044 3180 Forbidden: /api/rooms/73a792c8-cfc7-4f7e-9ecb-a943b4c05776/activity/
WARNING 2025-08-07 02:28:22,856 log 8044 3180 Forbidden: /api/rooms/73a792c8-cfc7-4f7e-9ecb-a943b4c05776/activity/
WARNING 2025-08-07 02:28:24,833 log 8044 3180 Forbidden: /api/rooms/73a792c8-cfc7-4f7e-9ecb-a943b4c05776/activity/
WARNING 2025-08-07 02:28:26,848 log 8044 3180 Forbidden: /api/rooms/73a792c8-cfc7-4f7e-9ecb-a943b4c05776/activity/
WARNING 2025-08-07 02:28:28,847 log 8044 3180 Forbidden: /api/rooms/73a792c8-cfc7-4f7e-9ecb-a943b4c05776/activity/
WARNING 2025-08-07 02:28:30,845 log 8044 3180 Forbidden: /api/rooms/73a792c8-cfc7-4f7e-9ecb-a943b4c05776/activity/
WARNING 2025-08-07 02:28:32,888 log 8044 3180 Forbidden: /api/rooms/73a792c8-cfc7-4f7e-9ecb-a943b4c05776/activity/
WARNING 2025-08-07 02:28:34,852 log 8044 3180 Forbidden: /api/rooms/73a792c8-cfc7-4f7e-9ecb-a943b4c05776/activity/
WARNING 2025-08-07 02:28:36,838 log 8044 3180 Forbidden: /api/rooms/73a792c8-cfc7-4f7e-9ecb-a943b4c05776/activity/
WARNING 2025-08-07 02:28:38,868 log 8044 3180 Forbidden: /api/rooms/73a792c8-cfc7-4f7e-9ecb-a943b4c05776/activity/
WARNING 2025-08-07 02:28:40,854 log 8044 3180 Forbidden: /api/rooms/73a792c8-cfc7-4f7e-9ecb-a943b4c05776/activity/
WARNING 2025-08-07 02:28:42,871 log 8044 3180 Forbidden: /api/rooms/73a792c8-cfc7-4f7e-9ecb-a943b4c05776/activity/
WARNING 2025-08-07 02:28:44,852 log 8044 3180 Forbidden: /api/rooms/73a792c8-cfc7-4f7e-9ecb-a943b4c05776/activity/
WARNING 2025-08-07 02:28:46,154 log 8044 16596 Forbidden: /api/rooms/b1befc26-6ecd-4f9b-8859-0e2f3bcd5280/activity/
WARNING 2025-08-07 02:28:46,857 log 8044 3180 Forbidden: /api/rooms/73a792c8-cfc7-4f7e-9ecb-a943b4c05776/activity/
WARNING 2025-08-07 02:28:48,853 log 8044 3180 Forbidden: /api/rooms/73a792c8-cfc7-4f7e-9ecb-a943b4c05776/activity/
WARNING 2025-08-07 02:28:50,850 log 8044 3180 Forbidden: /api/rooms/73a792c8-cfc7-4f7e-9ecb-a943b4c05776/activity/
WARNING 2025-08-07 02:28:52,861 log 8044 3180 Forbidden: /api/rooms/73a792c8-cfc7-4f7e-9ecb-a943b4c05776/activity/
WARNING 2025-08-07 02:28:54,840 log 8044 3180 Forbidden: /api/rooms/73a792c8-cfc7-4f7e-9ecb-a943b4c05776/activity/
WARNING 2025-08-07 02:28:56,850 log 8044 3180 Forbidden: /api/rooms/73a792c8-cfc7-4f7e-9ecb-a943b4c05776/activity/
WARNING 2025-08-07 02:28:58,852 log 8044 3180 Forbidden: /api/rooms/73a792c8-cfc7-4f7e-9ecb-a943b4c05776/activity/
WARNING 2025-08-07 02:29:00,852 log 8044 3180 Forbidden: /api/rooms/73a792c8-cfc7-4f7e-9ecb-a943b4c05776/activity/
WARNING 2025-08-07 02:29:07,522 log 8044 5400 Forbidden: /api/auth/login/
WARNING 2025-08-07 02:29:46,143 log 8044 16596 Forbidden: /api/rooms/b1befc26-6ecd-4f9b-8859-0e2f3bcd5280/activity/
INFO 2025-08-07 02:32:35,002 autoreload 3552 26212 Watching for file changes with StatReloader
WARNING 2025-08-07 02:32:37,306 log 3552 28312 Forbidden: /api/auth/login/
WARNING 2025-08-07 02:32:41,969 log 3552 28312 Not Found: /favicon.ico
WARNING 2025-08-07 02:32:46,214 log 3552 8280 Forbidden: /api/rooms/b1befc26-6ecd-4f9b-8859-0e2f3bcd5280/activity/
WARNING 2025-08-07 02:32:48,253 log 3552 28312 Forbidden: /api/auth/login/
WARNING 2025-08-07 02:32:59,093 log 3552 32016 Not Found: /favicon.ico
WARNING 2025-08-07 02:33:03,894 log 3552 32016 Forbidden: /api/auth/login/
WARNING 2025-08-07 02:33:28,988 log 3552 8280 Forbidden: /api/auth/login/
WARNING 2025-08-07 02:33:42,635 log 3552 8280 Forbidden: /api/auth/login/
WARNING 2025-08-07 02:33:46,200 log 3552 8280 Forbidden: /api/rooms/b1befc26-6ecd-4f9b-8859-0e2f3bcd5280/activity/
WARNING 2025-08-07 02:33:52,593 log 3552 31272 Not Found: /favicon.ico
WARNING 2025-08-07 02:34:22,451 log 3552 8280 Forbidden: /api/auth/login/
WARNING 2025-08-07 02:34:36,523 log 3552 11244 Forbidden: /api/auth/login/
WARNING 2025-08-07 02:34:46,177 log 3552 11244 Forbidden: /api/rooms/b1befc26-6ecd-4f9b-8859-0e2f3bcd5280/activity/
WARNING 2025-08-07 02:34:46,428 log 3552 16124 Forbidden: /api/auth/login/
WARNING 2025-08-07 02:35:09,949 log 3552 19916 Not Found: /favicon.ico
WARNING 2025-08-07 02:35:46,155 log 3552 11244 Forbidden: /api/rooms/b1befc26-6ecd-4f9b-8859-0e2f3bcd5280/activity/
WARNING 2025-08-07 02:35:51,077 log 3552 19916 Not Found: /.well-known/appspecific/com.chrome.devtools.json
WARNING 2025-08-07 02:36:42,485 log 3552 19916 Not Found: /api/admin/overview-stats/
WARNING 2025-08-07 02:36:46,168 log 3552 11244 Forbidden: /api/rooms/b1befc26-6ecd-4f9b-8859-0e2f3bcd5280/activity/
WARNING 2025-08-07 02:36:46,815 log 3552 19916 Forbidden: /api/auth/login/
WARNING 2025-08-07 02:36:59,253 log 3552 25540 Bad Request: /api/auth/login/
WARNING 2025-08-07 02:37:04,263 log 3552 25540 Bad Request: /api/auth/login/
WARNING 2025-08-07 02:37:08,253 log 3552 19916 Forbidden: /api/auth/login/
WARNING 2025-08-07 02:37:11,571 log 3552 11244 Forbidden: /api/rooms/b1befc26-6ecd-4f9b-8859-0e2f3bcd5280/activity/
WARNING 2025-08-07 02:37:12,589 log 3552 11244 Forbidden: /api/rooms/b1befc26-6ecd-4f9b-8859-0e2f3bcd5280/activity/
INFO 2025-08-07 02:37:18,060 autoreload 10860 31272 Watching for file changes with StatReloader
WARNING 2025-08-07 02:37:18,591 log 10860 22704 Forbidden: /api/rooms/b1befc26-6ecd-4f9b-8859-0e2f3bcd5280/activity/
WARNING 2025-08-07 02:37:20,569 log 10860 22704 Forbidden: /api/rooms/b1befc26-6ecd-4f9b-8859-0e2f3bcd5280/activity/
WARNING 2025-08-07 02:37:22,577 log 10860 22704 Forbidden: /api/rooms/b1befc26-6ecd-4f9b-8859-0e2f3bcd5280/activity/
INFO 2025-08-07 02:37:28,447 autoreload 11460 3840 Watching for file changes with StatReloader
WARNING 2025-08-07 02:38:19,074 log 11460 13556 Not Found: /api/admin/overview-stats/
WARNING 2025-08-07 02:38:25,219 log 11460 13556 Not Found: /.well-known/appspecific/com.chrome.devtools.json
WARNING 2025-08-07 02:38:31,126 log 11460 13556 Forbidden: /api/auth/login/
INFO 2025-08-07 02:42:08,563 autoreload 21576 3860 Watching for file changes with StatReloader
WARNING 2025-08-07 02:42:28,827 log 21576 6984 Bad Request: /api/auth/login/
